Workbook

Sheet Daftar Agen Pojok Statistik UI
A1: Pengurus Inti | D1: Analisis Data | G1: Pelayanan dan Konsultasi | J1: Media Kreatif
A2: No | B2: Nama Agen | D2: No | E2: Nama Agen | G2: No | H2: Nama Agen | J2: No | K2: Nama Agen
A3: 1 | B3: Taslim Ismail Anshorullah | D3: 1 | E3: Muhammad Binar Raffi Lazzuardi | G3: 1 | H3: Mohammad Aqsha Dwinovryan | J3: 1 | K3: Hylmi Savero Ijraba
A4: 2 | B4: Evanz Kizito | D4: 2 | E4: Nasywaa Rahmadhanti Fauzi | G4: 2 | H4: Surya Winaldi Yakin | J4: 2 | K4: Andrea Ratu Felia
A5: 3 | B5: Azmy Qonita | D5: 3 | E5: Adrian Dwi Mahendra | G5: 3 | H5: Alya Dwi Nurmiyati | J5: 3 | K5: Callysta Nadira Suhaidi
A6: 4 | B6: Azka Tsabbita | D6: 4 | E6: Genisha Almyra Mumtaz | G6: 4 | H6: Bagas Aryo Wicaksono | J6: 4 | K6: Akbar Reshan Fekran Muhammad
A7: 5 | B7: Alif Ramdhani Izharulhaq | D7: 5 | E7: Azka Safira Amorizki | G7: 5 | H7: Dastin Rangga Berani | J7: 5 | K7: Marc Constantine Lee Prijanto
D8: 6 | E8: Ilea Putrisia | G8: 6 | H8: Fadhil Rusydi Hafizh | J8: 6 | K8: Luna Hafijhah
D9: 7 | E9: Khalisha Zhurifah Sejati | G9: 7 | H9: Febinadia Salsabila | J9: 7 | K9: Aisya Az - Zahra Putri Fadi
D10: 8 | E10: Khansa Putri Indira | G10: 8 | H10: Gusti Agung Ayu Savithri Nirmalasari | J10: 8 | K10: Alifia Febrina
D11: 9 | E11: Miguel | G11: 9 | H11: Maria Ellora Damarkasih | J11: 9 | K11: Zafira Khairina
D12: 10 | E12: Ralf Zidane Harry | G12: 10 | H12: Yossi Tri Rahmanda | J12: 10 | K12: Ilona Kalista Siti Dewinta
D13: 11 | E13: Ruben Gian Agustin | G13: 11 | H13: Najwa Aulia Putri | J13: 11 | K13: Putu Daiva Ardhiyanta Dharmadwipa
D14: 12 | E14: Satriyo Nur Hidayat | G14: 12 | H14: Reksa Utami | J14: 12 | K14: Resty Novika Febrilia
J15: 11 | K15: Putu Daiva Ardhiyanta Dharmadwipa
J16: 12 | K16: Resty Novika Febrilia

Sheet Jadwal Jaga
A1: 1.JADWAL JAGA OFFLINE
A2: SPO: SPO Pelayanan dan Konsultasi Offline 2026 PASTIKAN MEMBACA DAN MEMAHAMI SPO DARI AWAL HINGGA AKHIR
A3: NO | B3: PERHATIKAN
A4: 1 | B4: Semua Agen yang melakukan pelayanan dan konsultasi offline diwajibkan untuk; a. memiliki akun BPS dan b. melakukan absensi dengan akun BPS sesuai dengan jadwalnya.
A5: 2 | B5: Jika Agen tidak dapat melakukan pelayanan dan konsultasi offline, maka agen perlu melakukan mekanisme perizinan minimal 2 jam sebelum jadwal jaga pada Surya (ID LINE: suryawinaldi9).
A6: NARAHUBUNG: Surya (ID LINE: suryawinaldi9/WA 082342370171)
A7: No | B7: Senin | D7: Selasa | F7: Rabu | H7: Kamis | J7: Jum'at
B8: Pagi 10.00 - 12.30 | C8: Siang 12.30 - 15.00 | D8: Pagi 10.00 - 12.30 | E8: Siang 12.30 - 15.00 | F8: Pagi 10.00 - 12.30 | G8: Siang 12.30 - 15.00 | H8: Pagi 10.00 - 12.30 | I8: Siang 12.30 - 15.00 | J8: Pagi 10.00 - 11.30 | K8: Siang 13.15 - 15.00
A9: 1 | C9: Reksa Utami | D9: Bagas Aryo Wicaksono | E9: Fadhil Rusydi Hafizh | F9: Febinadia Salsabila | G9: Dastin Rangga Berani | I9: Alya Dwi Nurmiyati | J9: Surya Winaldi Yakin | K9: Maria Ellora Damarkasih
A10: 2 | C10: Azka Tsabbita | D10: Yossi Tri Rahmanda | E10: Najwa Aulia Putri | F10: Satriyo Nur Hidayat | G10: Gusti Agung Ayu Savithri Nirmalasari | I10: Mohammad Aqsha Dwinovryan | J10: Azmy Qonita | K10: Miguel
A11: 3 | C11: Khansa Putri Indira | D11: Ilea Putrisia | E11: Callysta Nadira Suhaidi | F11: Marc Constantine Lee Prijanto | G11: Muhammad Binar Raffi Lazzuardi | I11: Evans Kizito | J11: Alif Ramdhani Izharulhaq | K11: Zafira Khairina
A12: 4 | C12: Luna Hafijhah | D12: Nasywaa Rahmadhanti Fauzi | E12: Adrian Dwi Mahendra | F12: Ilona Kalista Siti Dewinta | G12: Ralf Zidane Harry | I12: Azka Safira Amorizki | J12: Alifia Febrina | K12: Akbar Reshan Fekran Muhammad
A13: 5 | C13: Taslim Ismail Anshorullah | F13: Resty Novika Febrilia | G13: Khalisha Zhurifah Sejati | I13: Ruben Gian Agustin | J13: Putu Daiva Ardhiyanta Dharmadwipa | K13: Hylmi Savero Ijraba
A14: 6 | C14: Andrea Ratu Felia | I14: Genisha Almyra Mumtaz
A15: 7

Sheet Rekap Denda
A1: REKAP DENDA AGEN POJOK STATISTIK UI 2026 PARUH 2
C2: TOTAL (AGT - DES 2026) | F2: REKAP PER BULAN - TOTAL DENDA (Rp) | K2: REKAP PER MINGGU - TOTAL DENDA (Rp)
A3: No | B3: Nama Agen | C3: Jumlah Telat | D3: Jumlah Tdk Masuk | E3: Total Denda (Rp) | F3: Agustus | G3: September | H3: Oktober | I3: November | J3: Desember | K3: Mgg 1 31/08 | L3: Mgg 2 07/09 | M3: Mgg 3 14/09 | N3: Mgg 4 21/09 | O3: Mgg 5 28/09 | P3: Mgg 6 05/10 | Q3: Mgg 7 12/10 | R3: Mgg 8 19/10 | S3: Mgg 9 26/10 | T3: Mgg 10 02/11 | U3: Mgg 11 09/11 | V3: Mgg 12 16/11 | W3: Mgg 13 23/11 | X3: Mgg 14 30/11 | Y3: Mgg 15 07/12 | Z3: Mgg 16 14/12 | AA3: Mgg 17 21/12 | AB3: Mgg 18 28/12 | AC3: Mgg 19 04/01 | AD3: Mgg 20 11/01
A4: 1 | B4: Yossi Tri Rahmanda | C4: =COUNTIFS(Senin!$C$7:$C$146,$B4,Senin!$G$7:$G$146,"Ya",Senin!$E$7:$E$146,"<>")+COUNTIFS(Selasa!$C$7:$C$166,$B4,Selasa!$G$7:$G$166,"Ya",Selasa!$E$7:$E$166,"<>")+COUNTIFS(Rabu!$C$7:$C$206,$B4,Rabu!$G$7:$G$206,"Ya",Rabu!$E$7:$E$206,"<>")+COUNTIFS(Kamis!$C$7:$C$186,$B4,Kamis!$G$7:$G$186,"Ya",Kamis!$E$7:$E$186,"<>")+COUNTIFS(Jumat!$C$7:$C$186,$B4,Jumat!$G$7:$G$186,"Ya",Jumat!$E$7:$E$186,"<>") -> 0 | D4: =COUNTIFS(Senin!$C$7:$C$146,$B4,Senin!$G$7:$G$146,"Ya",Senin!$E$7:$E$146,"")+COUNTIFS(Selasa!$C$7:$C$166,$B4,Selasa!$G$7:$G$166,"Ya",Selasa!$E$7:$E$166,"")+COUNTIFS(Rabu!$C$7:$C$206,$B4,Rabu!$G$7:$G$206,"Ya",Rabu!$E$7:$E$206,"")+COUNTIFS(Kamis!$C$7:$C$186,$B4,Kamis!$G$7:$G$186,"Ya",Kamis!$E$7:$E$186,"")+COUNTIFS(Jumat!$C$7:$C$186,$B4,Jumat!$G$7:$G$186,"Ya",Jumat!$E$7:$E$186,"") -> 0 | E4: =SUMIFS(Senin!$H$7:$H$146,Senin!$C$7:$C$146,$B4,Senin!$A$7:$A$146,">="&DATE(2026,8,1),Senin!$A$7:$A$146,"<="&DATE(2026,12,31))+SUMIFS(Selasa!$H$7:$H$166,Selasa!$C$7:$C$166,$B4,Selasa!$A$7:$A$166,">="&DATE(2026,8,1),Selasa!$A$7:$A$166,"<="&DATE(2026,12,31))+SUMIFS(Rabu!$H$7:$H$206,Rabu!$C$7:$C$206,$B4,Rabu!$A$7:$A$206,">="&DATE(2026,8,1),Rabu!$A$7:$A$206,"<="&DATE(2026,12,31))+SUMIFS(Kamis!$H$7:$H$186,Kamis!$C$7:$C$186,$B4,Kamis!$A$7:$A$186,">="&DATE(2026,8,1),Kamis!$A$7:$A$186,"<="&DATE(2026,12,31))+SUMIFS(Jumat!$H$7:$H$186,Jumat!$C$7:$C$186,$B4,Jumat!$A$7:$A$186,">="&DATE(2026,8,1),Jumat!$A$7:$A$186,"<="&DATE(2026,12,31)) -> 0 | F4: =SUMIFS(Senin!$H$7:$H$146,Senin!$C$7:$C$146,$B4,Senin!$A$7:$A$146,">="&DATE(2026,8,1),Senin!$A$7:$A$146,"<="&DATE(2026,8,31))+SUMIFS(Selasa!$H$7:$H$166,Selasa!$C$7:$C$166,$B4,Selasa!$A$7:$A$166,">="&DATE(2026,8,1),Selasa!$A$7:$A$166,"<="&DATE(2026,8,31))+SUMIFS(Rabu!$H$7:$H$206,Rabu!$C$7:$C$206,$B4,Rabu!$A$7:$A$206,">="&DATE(2026,8,1),Rabu!$A$7:$A$206,"<="&DATE(2026,8,31))+SUMIFS(Kamis!$H$7:$H$186,Kamis!$C$7:$C$186,$B4,Kamis!$A$7:$A$186,">="&DATE(2026,8,1),Kamis!$A$7:$A$186,"<="&DATE(2026,8,31))+SUMIFS(Jumat!$H$7:$H$186,Jumat!$C$7:$C$186,$B4,Jumat!$A$7:$A$186,">="&DATE(2026,8,1),Jumat!$A$7:$A$186,"<="&DATE(2026,8,31)) -> 0 | G4: =SUMIFS(Senin!$H$7:$H$146,Senin!$C$7:$C$146,$B4,Senin!$A$7:$A$146,">="&DATE(2026,9,1),Senin!$A$7:$A$146,"<="&DATE(2026,9,30))+SUMIFS(Selasa!$H$7:$H$166,Selasa!$C$7:$C$166,$B4,Selasa!$A$7:$A$166,">="&DATE(2026,9,1),Selasa!$A$7:$A$166,"<="&DATE(2026,9,30))+SUMIFS(Rabu!$H$7:$H$206,Rabu!$C$7:$C$206,$B4,Rabu!$A$7:$A$206,">="&DATE(2026,9,1),Rabu!$A$7:$A$206,"<="&DATE(2026,9,30))+SUMIFS(Kamis!$H$7:$H$186,Kamis!$C$7:$C$186,$B4,Kamis!$A$7:$A$186,">="&DATE(2026,9,1),Kamis!$A$7:$A$186,"<="&DATE(2026,9,30))+SUMIFS(Jumat!$H$7:$H$186,Jumat!$C$7:$C$186,$B4,Jumat!$A$7:$A$186,">="&DATE(2026,9,1),Jumat!$A$7:$A$186,"<="&DATE(2026,9,30)) -> 0 | H4: =SUMIFS(Senin!$H$7:$H$146,Senin!$C$7:$C$146,$B4,Senin!$A$7:$A$146,">="&DATE(2026,10,1),Senin!$A$7:$A$146,"<="&DATE(2026,10,31))+SUMIFS(Selasa!$H$7:$H$166,Selasa!$C$7:$C$166,$B4,Selasa!$A$7:$A$166,">="&DATE(2026,10,1),Selasa!$A$7:$A$166,"<="&DATE(2026,10,31))+SUMIFS(Rabu!$H$7:$H$206,Rabu!$C$7:$C$206,$B4,Rabu!$A$7:$A$206,">="&DATE(2026,10,1),Rabu!$A$7:$A$206,"<="&DATE(2026,10,31))+SUMIFS(Kamis!$H$7:$H$186,Kamis!$C$7:$C$186,$B4,Kamis!$A$7:$A$186,">="&DATE(2026,10,1),Kamis!$A$7:$A$186,"<="&DATE(2026,10,31))+SUMIFS(Jumat!$H$7:$H$186,Jumat!$C$7:$C$186,$B4,Jumat!$A$7:$A$186,">="&DATE(2026,10,1),Jumat!$A$7:$A$186,"<="&DATE(2026,10,31)) -> 0 | I4: =SUMIFS(Senin!$H$7:$H$146,Senin!$C$7:$C$146,$B4,Senin!$A$7:$A$146,">="&DATE(2026,11,1),Senin!$A$7:$A$146,"<="&DATE(2026,11,30))+SUMIFS(Selasa!$H$7:$H$166,Selasa!$C$7:$C$166,$B4,Selasa!$A$7:$A$166,">="&DATE(2026,11,1),Selasa!$A$7:$A$166,"<="&DATE(2026,11,30))+SUMIFS(Rabu!$H$7:$H$206,Rabu!$C$7:$C$206,$B4,Rabu!$A$7:$A$206,">="&DATE(2026,11,1),Rabu!$A$7:$A$206,"<="&DATE(2026,11,30))+SUMIFS(Kamis!$H$7:$H$186,Kamis!$C$7:$C$186,$B4,Kamis!$A$7:$A$186,">="&DATE(2026,11,1),Kamis!$A$7:$A$186,"<="&DATE(2026,11,30))+SUMIFS(Jumat!$H$7:$H$186,Jumat!$C$7:$C$186,$B4,Jumat!$A$7:$A$186,">="&DATE(2026,11,1),Jumat!$A$7:$A$186,"<="&DATE(2026,11,30)) -> 0 | J4: =SUMIFS(Senin!$H$7:$H$146,Senin!$C$7:$C$146,$B4,Senin!$A$7:$A$146,">="&DATE(2026,12,1),Senin!$A$7:$A$146,"<="&DATE(2026,12,31))+SUMIFS(Selasa!$H$7:$H$166,Selasa!$C$7:$C$166,$B4,Selasa!$A$7:$A$166,">="&DATE(2026,12,1),Selasa!$A$7:$A$166,"<="&DATE(2026,12,31))+SUMIFS(Rabu!$H$7:$H$206,Rabu!$C$7:$C$206,$B4,Rabu!$A$7:$A$206,">="&DATE(2026,12,1),Rabu!$A$7:$A$206,"<="&DATE(2026,12,31))+SUMIFS(Kamis!$H$7:$H$186,Kamis!$C$7:$C$186,$B4,Kamis!$A$7:$A$186,">="&DATE(2026,12,1),Kamis!$A$7:$A$186,"<="&DATE(2026,12,31))+SUMIFS(Jumat!$H$7:$H$186,Jumat!$C$7:$C$186,$B4,Jumat!$A$7:$A$186,">="&DATE(2026,12,1),Jumat!$A$7:$A$186,"<="&DATE(2026,12,31)) -> 0 | K4: =SUMIFS(Senin!$H$7:$H$146,Senin!$C$7:$C$146,$B4,Senin!$A$7:$A$146,">="&DATE(2026,8,31),Senin!$A$7:$A$146,"<="&DATE(2026,9,6))+SUMIFS(Selasa!$H$7:$H$166,Selasa!$C$7:$C$166,$B4,Selasa!$A$7:$A$166,">="&DATE(2026,8,31),Selasa!$A$7:$A$166,"<="&DATE(2026,9,6))+SUMIFS(Rabu!$H$7:$H$206,Rabu!$C$7:$C$206,$B4,Rabu!$A$7:$A$206,">="&DATE(2026,8,31),Rabu!$A$7:$A$206,"<="&DATE(2026,9,6))+SUMIFS(Kamis!$H$7:$H$186,Kamis!$C$7:$C$186,$B4,Kamis!$A$7:$A$186,">="&DATE(2026,8,31),Kamis!$A$7:$A$186,"<="&DATE(2026,9,6))+SUMIFS(Jumat!$H$7:$H$186,Jumat!$C$7:$C$186,$B4,Jumat!$A$7:$A$186,">="&DATE(2026,8,31),Jumat!$A$7:$A$186,"<="&DATE(2026,9,6)) -> 0 | L4: =SUMIFS(Senin!$H$7:$H$146,Senin!$C$7:$C$146,$B4,Senin!$A$7:$A$146,">="&DATE(2026,9,7),Senin!$A$7:$A$146,"<="&DATE(2026,9,13))+SUMIFS(Selasa!$H$7:$H$166,Selasa!$C$7:$C$166,$B4,Selasa!$A$7:$A$166,">="&DATE(2026,9,7),Selasa!$A$7:$A$166,"<="&DATE(2026,9,13))+SUMIFS(Rabu!$H$7:$H$206,Rabu!$C$7:$C$206,$B4,Rabu!$A$7:$A$206,">="&DATE(2026,9,7),Rabu!$A$7:$A$206,"<="&DATE(2026,9,13))+SUMIFS(Kamis!$H$7:$H$186,Kamis!$C$7:$C$186,$B4,Kamis!$A$7:$A$186,">="&DATE(2026,9,7),Kamis!$A$7:$A$186,"<="&DATE(2026,9,13))+SUMIFS(Jumat!$H$7:$H$186,Jumat!$C$7:$C$186,$B4,Jumat!$A$7:$A$186,">="&DATE(2026,9,7),Jumat!$A$7:$A$186,"<="&DATE(2026,9,13)) -> 0 | M4: =SUMIFS(Senin!$H$7:$H$146,Senin!$C$7:$C$146,$B4,Senin!$A$7:$A$146,">="&DATE(2026,9,14),Senin!$A$7:$A$146,"<="&DATE(2026,9,20))+SUMIFS(Selasa!$H$7:$H$166,Selasa!$C$7:$C$166,$B4,Selasa!$A$7:$A$166,">="&DATE(2026,9,14),Selasa!$A$7:$A$166,"<="&DATE(2026,9,20))+SUMIFS(Rabu!$H$7:$H$206,Rabu!$C$7:$C$206,$B4,Rabu!$A$7:$A$206,">="&DATE(2026,9,14),Rabu!$A$7:$A$206,"<="&DATE(2026,9,20))+SUMIFS(Kamis!$H$7:$H$186,Kamis!$C$7:$C$186,$B4,Kamis!$A$7:$A$186,">="&DATE(2026,9,14),Kamis!$A$7:$A$186,"<="&DATE(2026,9,20))+SUMIFS(Jumat!$H$7:$H$186,Jumat!$C$7:$C$186,$B4,Jumat!$A$7:$A$186,">="&DATE(2026,9,14),Jumat!$A$7:$A$186,"<="&DATE(2026,9,20)) -> 0 | N4: =SUMIFS(Senin!$H$7:$H$146,Senin!$C$7:$C$146,$B4,Senin!$A$7:$A$146,">="&DATE(2026,9,21),Senin!$A$7:$A$146,"<="&DATE(2026,9,27))+SUMIFS(Selasa!$H$7:$H$166,Selasa!$C$7:$C$166,$B4,Selasa!$A$7:$A$166,">="&DATE(2026,9,21),Selasa!$A$7:$A$166,"<="&DATE(2026,9,27))+SUMIFS(Rabu!$H$7:$H$206,Rabu!$C$7:$C$206,$B4,Rabu!$A$7:$A$206,">="&DATE(2026,9,21),Rabu!$A$7:$A$206,"<="&DATE(2026,9,27))+SUMIFS(Kamis!$H$7:$H$186,Kamis!$C$7:$C$186,$B4,Kamis!$A$7:$A$186,">="&DATE(2026,9,21),Kamis!$A$7:$A$186,"<="&DATE(2026,9,27))+SUMIFS(Jumat!$H$7:$H$186,Jumat!$C$7:$C$186,$B4,Jumat!$A$7:$A$186,">="&DATE(2026,9,21),Jumat!$A$7:$A$186,"<="&DATE(2026,9,27)) -> 0 | O4: =SUMIFS(Senin!$H$7:$H$146,Senin!$C$7:$C$146,$B4,Senin!$A$7:$A$146,">="&DATE(2026,9,28),Senin!$A$7:$A$146,"<="&DATE(2026,10,4))+SUMIFS(Selasa!$H$7:$H$166,Selasa!$C$7:$C$166,$B4,Selasa!$A$7:$A$166,">="&DATE(2026,9,28),Selasa!$A$7:$A$166,"<="&DATE(2026,10,4))+SUMIFS(Rabu!$H$7:$H$206,Rabu!$C$7:$C$206,$B4,Rabu!$A$7:$A$206,">="&DATE(2026,9,28),Rabu!$A$7:$A$206,"<="&DATE(2026,10,4))+SUMIFS(Kamis!$H$7:$H$186,Kamis!$C$7:$C$186,$B4,Kamis!$A$7:$A$186,">="&DATE(2026,9,28),Kamis!$A$7:$A$186,"<="&DATE(2026,10,4))+SUMIFS(Jumat!$H$7:$H$186,Jumat!$C$7:$C$186,$B4,Jumat!$A$7:$A$186,">="&DATE(2026,9,28),Jumat!$A$7:$A$186,"<="&DATE(2026,10,4)) -> 0 | P4: =SUMIFS(Senin!$H$7:$H$146,Senin!$C$7:$C$146,$B4,Senin!$A$7:$A$146,">="&DATE(2026,10,5),Senin!$A$7:$A$146,"<="&DATE(2026,10,11))+SUMIFS(Selasa!$H$7:$H$166,Selasa!$C$7:$C$166,$B4,Selasa!$A$7:$A$166,">="&DATE(2026,10,5),Selasa!$A$7:$A$166,"<="&DATE(2026,10,11))+SUMIFS(Rabu!$H$7:$H$206,Rabu!$C$7:$C$206,$B4,Rabu!$A$7:$A$206,">="&DATE(2026,10,5),Rabu!$A$7:$A$206,"<="&DATE(2026,10,11))+SUMIFS(Kamis!$H$7:$H$186,Kamis!$C$7:$C$186,$B4,Kamis!$A$7:$A$186,">="&DATE(2026,10,5),Kamis!$A$7:$A$186,"<="&DATE(2026,10,11))+SUMIFS(Jumat!$H$7:$H$186,Jumat!$C$7:$C$186,$B4,Jumat!$A$7:$A$186,">="&DATE(2026,10,5),Jumat!$A$7:$A$186,"<="&DATE(2026,10,11)) -> 0 | Q4: =SUMIFS(Senin!$H$7:$H$146,Senin!$C$7:$C$146,$B4,Senin!$A$7:$A$146,">="&DATE(2026,10,12),Senin!$A$7:$A$146,"<="&DATE(2026,10,18))+SUMIFS(Selasa!$H$7:$H$166,Selasa!$C$7:$C$166,$B4,Selasa!$A$7:$A$166,">="&DATE(2026,10,12),Selasa!$A$7:$A$166,"<="&DATE(2026,10,18))+SUMIFS(Rabu!$H$7:$H$206,Rabu!$C$7:$C$206,$B4,Rabu!$A$7:$A$206,">="&DATE(2026,10,12),Rabu!$A$7:$A$206,"<="&DATE(2026,10,18))+SUMIFS(Kamis!$H$7:$H$186,Kamis!$C$7:$C$186,$B4,Kamis!$A$7:$A$186,">="&DATE(2026,10,12),Kamis!$A$7:$A$186,"<="&DATE(2026,10,18))+SUMIFS(Jumat!$H$7:$H$186,Jumat!$C$7:$C$186,$B4,Jumat!$A$7:$A$186,">="&DATE(2026,10,12),Jumat!$A$7:$A$186,"<="&DATE(2026,10,18)) -> 0 | R4: =SUMIFS(Senin!$H$7:$H$146,Senin!$C$7:$C$146,$B4,Senin!$A$7:$A$146,">="&DATE(2026,10,19),Senin!$A$7:$A$146,"<="&DATE(2026,10,25))+SUMIFS(Selasa!$H$7:$H$166,Selasa!$C$7:$C$166,$B4,Selasa!$A$7:$A$166,">="&DATE(2026,10,19),Selasa!$A$7:$A$166,"<="&DATE(2026,10,25))+SUMIFS(Rabu!$H$7:$H$206,Rabu!$C$7:$C$206,$B4,Rabu!$A$7:$A$206,">="&DATE(2026,10,19),Rabu!$A$7:$A$206,"<="&DATE(2026,10,25))+SUMIFS(Kamis!$H$7:$H$186,Kamis!$C$7:$C$186,$B4,Kamis!$A$7:$A$186,">="&DATE(2026,10,19),Kamis!$A$7:$A$186,"<="&DATE(2026,10,25))+SUMIFS(Jumat!$H$7:$H$186,Jumat!$C$7:$C$186,$B4,Jumat!$A$7:$A$186,">="&DATE(2026,10,19),Jumat!$A$7:$A$186,"<="&DATE(2026,10,25)) -> 0 | S4: =SUMIFS(Senin!$H$7:$H$146,Senin!$C$7:$C$146,$B4,Senin!$A$7:$A$146,">="&DATE(2026,10,26),Senin!$A$7:$A$146,"<="&DATE(2026,11,1))+SUMIFS(Selasa!$H$7:$H$166,Selasa!$C$7:$C$166,$B4,Selasa!$A$7:$A$166,">="&DATE(2026,10,26),Selasa!$A$7:$A$166,"<="&DATE(2026,11,1))+SUMIFS(Rabu!$H$7:$H$206,Rabu!$C$7:$C$206,$B4,Rabu!$A$7:$A$206,">="&DATE(2026,10,26),Rabu!$A$7:$A$206,"<="&DATE(2026,11,1))+SUMIFS(Kamis!$H$7:$H$186,Kamis!$C$7:$C$186,$B4,Kamis!$A$7:$A$186,">="&DATE(2026,10,26),Kamis!$A$7:$A$186,"<="&DATE(2026,11,1))+SUMIFS(Jumat!$H$7:$H$186,Jumat!$C$7:$C$186,$B4,Jumat!$A$7:$A$186,">="&DATE(2026,10,26),Jumat!$A$7:$A$186,"<="&DATE(2026,11,1)) -> 0 | T4: =SUMIFS(Senin!$H$7:$H$146,Senin!$C$7:$C$146,$B4,Senin!$A$7:$A$146,">="&DATE(2026,11,2),Senin!$A$7:$A$146,"<="&DATE(2026,11,8))+SUMIFS(Selasa!$H$7:$H$166,Selasa!$C$7:$C$166,$B4,Selasa!$A$7:$A$166,">="&DATE(2026,11,2),Selasa!$A$7:$A$166,"<="&DATE(2026,11,8))+SUMIFS(Rabu!$H$7:$H$206,Rabu!$C$7:$C$206,$B4,Rabu!$A$7:$A$206,">="&DATE(2026,11,2),Rabu!$A$7:$A$206,"<="&DATE(2026,11,8))+SUMIFS(Kamis!$H$7:$H$186,Kamis!$C$7:$C$186,$B4,Kamis!$A$7:$A$186,">="&DATE(2026,11,2),Kamis!$A$7:$A$186,"<="&DATE(2026,11,8))+SUMIFS(Jumat!$H$7:$H$186,Jumat!$C$7:$C$186,$B4,Jumat!$A$7:$A$186,">="&DATE(2026,11,2),Jumat!$A$7:$A$186,"<="&DATE(2026,11,8)) -> 0 | U4: =SUMIFS(Senin!$H$7:$H$146,Senin!$C$7:$C$146,$B4,Senin!$A$7:$A$146,">="&DATE(2026,11,9),Senin!$A$7:$A$146,"<="&DATE(2026,11,15))+SUMIFS(Selasa!$H$7:$H$166,Selasa!$C$7:$C$166,$B4,Selasa!$A$7:$A$166,">="&DATE(2026,11,9),Selasa!$A$7:$A$166,"<="&DATE(2026,11,15))+SUMIFS(Rabu!$H$7:$H$206,Rabu!$C$7:$C$206,$B4,Rabu!$A$7:$A$206,">="&DATE(2026,11,9),Rabu!$A$7:$A$206,"<="&DATE(2026,11,15))+SUMIFS(Kamis!$H$7:$H$186,Kamis!$C$7:$C$186,$B4,Kamis!$A$7:$A$186,">="&DATE(2026,11,9),Kamis!$A$7:$A$186,"<="&DATE(2026,11,15))+SUMIFS(Jumat!$H$7:$H$186,Jumat!$C$7:$C$186,$B4,Jumat!$A$7:$A$186,">="&DATE(2026,11,9),Jumat!$A$7:$A$186,"<="&DATE(2026,11,15)) -> 0 | V4: =SUMIFS(Senin!$H$7:$H$146,Senin!$C$7:$C$146,$B4,Senin!$A$7:$A$146,">="&DATE(2026,11,16),Senin!$A$7:$A$146,"<="&DATE(2026,11,22))+SUMIFS(Selasa!$H$7:$H$166,Selasa!$C$7:$C$166,$B4,Selasa!$A$7:$A$166,">="&DATE(2026,11,16),Selasa!$A$7:$A$166,"<="&DATE(2026,11,22))+SUMIFS(Rabu!$H$7:$H$206,Rabu!$C$7:$C$206,$B4,Rabu!$A$7:$A$206,">="&DATE(2026,11,16),Rabu!$A$7:$A$206,"<="&DATE(2026,11,22))+SUMIFS(Kamis!$H$7:$H$186,Kamis!$C$7:$C$186,$B4,Kamis!$A$7:$A$186,">="&DATE(2026,11,16),Kamis!$A$7:$A$186,"<="&DATE(2026,11,22))+SUMIFS(Jumat!$H$7:$H$186,Jumat!$C$7:$C$186,$B4,Jumat!$A$7:$A$186,">="&DATE(2026,11,16),Jumat!$A$7:$A$186,"<="&DATE(2026,11,22)) -> 0 | W4: =SUMIFS(Senin!$H$7:$H$146,Senin!$C$7:$C$146,$B4,Senin!$A$7:$A$146,">="&DATE(2026,11,23),Senin!$A$7:$A$146,"<="&DATE(2026,11,29))+SUMIFS(Selasa!$H$7:$H$166,Selasa!$C$7:$C$166,$B4,Selasa!$A$7:$A$166,">="&DATE(2026,11,23),Selasa!$A$7:$A$166,"<="&DATE(2026,11,29))+SUMIFS(Rabu!$H$7:$H$206,Rabu!$C$7:$C$206,$B4,Rabu!$A$7:$A$206,">="&DATE(2026,11,23),Rabu!$A$7:$A$206,"<="&DATE(2026,11,29))+SUMIFS(Kamis!$H$7:$H$186,Kamis!$C$7:$C$186,$B4,Kamis!$A$7:$A$186,">="&DATE(2026,11,23),Kamis!$A$7:$A$186,"<="&DATE(2026,11,29))+SUMIFS(Jumat!$H$7:$H$186,Jumat!$C$7:$C$186,$B4,Jumat!$A$7:$A$186,">="&DATE(2026,11,23),Jumat!$A$7:$A$186,"<="&DATE(2026,11,29)) -> 0 | X4: =SUMIFS(Senin!$H$7:$H$146,Senin!$C$7:$C$146,$B4,Senin!$A$7:$A$146,">="&DATE(2026,11,30),Senin!$A$7:$A$146,"<="&DATE(2026,12,6))+SUMIFS(Selasa!$H$7:$H$166,Selasa!$C$7:$C$166,$B4,Selasa!$A$7:$A$166,">="&DATE(2026,11,30),Selasa!$A$7:$A$166,"<="&DATE(2026,12,6))+SUMIFS(Rabu!$H$7:$H$206,Rabu!$C$7:$C$206,$B4,Rabu!$A$7:$A$206,">="&DATE(2026,11,30),Rabu!$A$7:$A$206,"<="&DATE(2026,12,6))+SUMIFS(Kamis!$H$7:$H$186,Kamis!$C$7:$C$186,$B4,Kamis!$A$7:$A$186,">="&DATE(2026,11,30),Kamis!$A$7:$A$186,"<="&DATE(2026,12,6))+SUMIFS(Jumat!$H$7:$H$186,Jumat!$C$7:$C$186,$B4,Jumat!$A$7:$A$186,">="&DATE(2026,11,30),Jumat!$A$7:$A$186,"<="&DATE(2026,12,6)) -> 0 | Y4: =SUMIFS(Senin!$H$7:$H$146,Senin!$C$7:$C$146,$B4,Senin!$A$7:$A$146,">="&DATE(2026,12,7),Senin!$A$7:$A$146,"<="&DATE(2026,12,13))+SUMIFS(Selasa!$H$7:$H$166,Selasa!$C$7:$C$166,$B4,Selasa!$A$7:$A$166,">="&DATE(2026,12,7),Selasa!$A$7:$A$166,"<="&DATE(2026,12,13))+SUMIFS(Rabu!$H$7:$H$206,Rabu!$C$7:$C$206,$B4,Rabu!$A$7:$A$206,">="&DATE(2026,12,7),Rabu!$A$7:$A$206,"<="&DATE(2026,12,13))+SUMIFS(Kamis!$H$7:$H$186,Kamis!$C$7:$C$186,$B4,Kamis!$A$7:$A$186,">="&DATE(2026,12,7),Kamis!$A$7:$A$186,"<="&DATE(2026,12,13))+SUMIFS(Jumat!$H$7:$H$186,Jumat!$C$7:$C$186,$B4,Jumat!$A$7:$A$186,">="&DATE(2026,12,7),Jumat!$A$7:$A$186,"<="&DATE(2026,12,13)) -> 0 | Z4: =SUMIFS(Senin!$H$7:$H$146,Senin!$C$7:$C$146,$B4,Senin!$A$7:$A$146,">="&DATE(2026,12,14),Senin!$A$7:$A$146,"<="&DATE(2026,12,20))+SUMIFS(Selasa!$H$7:$H$166,Selasa!$C$7:$C$166,$B4,Selasa!$A$7:$A$166,">="&DATE(2026,12,14),Selasa!$A$7:$A$166,"<="&DATE(2026,12,20))+SUMIFS(Rabu!$H$7:$H$206,Rabu!$C$7:$C$206,$B4,Rabu!$A$7:$A$206,">="&DATE(2026,12,14),Rabu!$A$7:$A$206,"<="&DATE(2026,12,20))+SUMIFS(Kamis!$H$7:$H$186,Kamis!$C$7:$C$186,$B4,Kamis!$A$7:$A$186,">="&DATE(2026,12,14),Kamis!$A$7:$A$186,"<="&DATE(2026,12,20))+SUMIFS(Jumat!$H$7:$H$186,Jumat!$C$7:$C$186,$B4,Jumat!$A$7:$A$186,">="&DATE(2026,12,14),Jumat!$A$7:$A$186,"<="&DATE(2026,12,20)) -> 0 | AA4: =SUMIFS(Senin!$H$7:$H$146,Senin!$C$7:$C$146,$B4,Senin!$A$7:$A$146,">="&DATE(2026,12,21),Senin!$A$7:$A$146,"<="&DATE(2026,12,27))+SUMIFS(Selasa!$H$7:$H$166,Selasa!$C$7:$C$166,$B4,Selasa!$A$7:$A$166,">="&DATE(2026,12,21),Selasa!$A$7:$A$166,"<="&DATE(2026,12,27))+SUMIFS(Rabu!$H$7:$H$206,Rabu!$C$7:$C$206,$B4,Rabu!$A$7:$A$206,">="&DATE(2026,12,21),Rabu!$A$7:$A$206,"<="&DATE(2026,12,27))+SUMIFS(Kamis!$H$7:$H$186,Kamis!$C$7:$C$186,$B4,Kamis!$A$7:$A$186,">="&DATE(2026,12,21),Kamis!$A$7:$A$186,"<="&DATE(2026,12,27))+SUMIFS(Jumat!$H$7:$H$186,Jumat!$C$7:$C$186,$B4,Jumat!$A$7:$A$186,">="&DATE(2026,12,21),Jumat!$A$7:$A$186,"<="&DATE(2026,12,27)) -> 0 | AB4: =SUMIFS(Senin!$H$7:$H$146,Senin!$C$7:$C$146,$B4,Senin!$A$7:$A$146,">="&DATE(2026,12,28),Senin!$A$7:$A$146,"<="&DATE(2027,1,3))+SUMIFS(Selasa!$H$7:$H$166,Selasa!$C$7:$C$166,$B4,Selasa!$A$7:$A$166,">="&DATE(2026,12,28),Selasa!$A$7:$A$166,"<="&DATE(2027,1,3))+SUMIFS(Rabu!$H$7:$H$206,Rabu!$C$7:$C$206,$B4,Rabu!$A$7:$A$206,">="&DATE(2026,12,28),Rabu!$A$7:$A$206,"<="&DATE(2027,1,3))+SUMIFS(Kamis!$H$7:$H$186,Kamis!$C$7:$C$186,$B4,Kamis!$A$7:$A$186,">="&DATE(2026,12,28),Kamis!$A$7:$A$186,"<="&DATE(2027,1,3))+SUMIFS(Jumat!$H$7:$H$186,Jumat!$C$7:$C$186,$B4,Jumat!$A$7:$A$186,">="&DATE(2026,12,28),Jumat!$A$7:$A$186,"<="&DATE(2027,1,3)) -> 0 | AC4: =SUMIFS(Senin!$H$7:$H$146,Senin!$C$7:$C$146,$B4,Senin!$A$7:$A$146,">="&DATE(2027,1,4),Senin!$A$7:$A$146,"<="&DATE(2027,1,10))+SUMIFS(Selasa!$H$7:$H$166,Selasa!$C$7:$C$166,$B4,Selasa!$A$7:$A$166,">="&DATE(2027,1,4),Selasa!$A$7:$A$166,"<="&DATE(2027,1,10))+SUMIFS(Rabu!$H$7:$H$206,Rabu!$C$7:$C$206,$B4,Rabu!$A$7:$A$206,">="&DATE(2027,1,4),Rabu!$A$7:$A$206,"<="&DATE(2027,1,10))+SUMIFS(Kamis!$H$7:$H$186,Kamis!$C$7:$C$186,$B4,Kamis!$A$7:$A$186,">="&DATE(2027,1,4),Kamis!$A$7:$A$186,"<="&DATE(2027,1,10))+SUMIFS(Jumat!$H$7:$H$186,Jumat!$C$7:$C$186,$B4,Jumat!$A$7:$A$186,">="&DATE(2027,1,4),Jumat!$A$7:$A$186,"<="&DATE(2027,1,10)) -> 0 | AD4: =SUMIFS(Senin!$H$7:$H$146,Senin!$C$7:$C$146,$B4,Senin!$A$7:$A$146,">="&DATE(2027,1,11),Senin!$A$7:$A$146,"<="&DATE(2027,1,17))+SUMIFS(Selasa!$H$7:$H$166,Selasa!$C$7:$C$166,$B4,Selasa!$A$7:$A$166,">="&DATE(2027,1,11),Selasa!$A$7:$A$166,"<="&DATE(2027,1,17))+SUMIFS(Rabu!$H$7:$H$206,Rabu!$C$7:$C$206,$B4,Rabu!$A$7:$A$206,">="&DATE(2027,1,11),Rabu!$A$7:$A$206,"<="&DATE(2027,1,17))+SUMIFS(Kamis!$H$7:$H$186,Kamis!$C$7:$C$186,$B4,Kamis!$A$7:$A$186,">="&DATE(2027,1,11),Kamis!$A$7:$A$186,"<="&DATE(2027,1,17))+SUMIFS(Jumat!$H$7:$H$186,Jumat!$C$7:$C$186,$B4,Jumat!$A$7:$A$186,">="&DATE(2027,1,11),Jumat!$A$7:$A$186,"<="&DATE(2027,1,17)) -> 0
A5: 2 | B5: Mohammad Aqsha Dwinovryan | C5: =COUNTIFS(Senin!$C$7:$C$146,$B5,Senin!$G$7:$G$146,"Ya",Senin!$E$7:$E$146,"<>")+COUNTIFS(Selasa!$C$7:$C$166,$B5,Selasa!$G$7:$G$166,"Ya",Selasa!$E$7:$E$166,"<>")+COUNTIFS(Rabu!$C$7:$C$206,$B5,Rabu!$G$7:$G$206,"Ya",Rabu!$E$7:$E$206,"<>")+COUNTIFS(Kamis!$C$7:$C$186,$B5,Kamis!$G$7:$G$186,"Ya",Kamis!$E$7:$E$186,"<>")+COUNTIFS(Jumat!$C$7:$C$186,$B5,Jumat!$G$7:$G$186,"Ya",Jumat!$E$7:$E$186,"<>") -> 0 | D5: =COUNTIFS(Senin!$C$7:$C$146,$B5,Senin!$G$7:$G$146,"Ya",Senin!$E$7:$E$146,"")+COUNTIFS(Selasa!$C$7:$C$166,$B5,Selasa!$G$7:$G$166,"Ya",Selasa!$E$7:$E$166,"")+COUNTIFS(Rabu!$C$7:$C$206,$B5,Rabu!$G$7:$G$206,"Ya",Rabu!$E$7:$E$206,"")+COUNTIFS(Kamis!$C$7:$C$186,$B5,Kamis!$G$7:$G$186,"Ya",Kamis!$E$7:$E$186,"")+COUNTIFS(Jumat!$C$7:$C$186,$B5,Jumat!$G$7:$G$186,"Ya",Jumat!$E$7:$E$186,"") -> 0 | E5: =SUMIFS(Senin!$H$7:$H$146,Senin!$C$7:$C$146,$B5,Senin!$A$7:$A$146,">="&DATE(2026,8,1),Senin!$A$7:$A$146,"<="&DATE(2026,12,31))+SUMIFS(Selasa!$H$7:$H$166,Selasa!$C$7:$C$166,$B5,Selasa!$A$7:$A$166,">="&DATE(2026,8,1),Selasa!$A$7:$A$166,"<="&DATE(2026,12,31))+SUMIFS(Rabu!$H$7:$H$206,Rabu!$C$7:$C$206,$B5,Rabu!$A$7:$A$206,">="&DATE(2026,8,1),Rabu!$A$7:$A$206,"<="&DATE(2026,12,31))+SUMIFS(Kamis!$H$7:$H$186,Kamis!$C$7:$C$186,$B5,Kamis!$A$7:$A$186,">="&DATE(2026,8,1),Kamis!$A$7:$A$186,"<="&DATE(2026,12,31))+SUMIFS(Jumat!$H$7:$H$186,Jumat!$C$7:$C$186,$B5,Jumat!$A$7:$A$186,">="&DATE(2026,8,1),Jumat!$A$7:$A$186,"<="&DATE(2026,12,31)) -> 0 | F5: =SUMIFS(Senin!$H$7:$H$146,Senin!$C$7:$C$146,$B5,Senin!$A$7:$A$146,">="&DATE(2026,8,1),Senin!$A$7:$A$146,"<="&DATE(2026,8,31))+SUMIFS(Selasa!$H$7:$H$166,Selasa!$C$7:$C$166,$B5,Selasa!$A$7:$A$166,">="&DATE(2026,8,1),Selasa!$A$7:$A$166,"<="&DATE(2026,8,31))+SUMIFS(Rabu!$H$7:$H$206,Rabu!$C$7:$C$206,$B5,Rabu!$A$7:$A$206,">="&DATE(2026,8,1),Rabu!$A$7:$A$206,"<="&DATE(2026,8,31))+SUMIFS(Kamis!$H$7:$H$186,Kamis!$C$7:$C$186,$B5,Kamis!$A$7:$A$186,">="&DATE(2026,8,1),Kamis!$A$7:$A$186,"<="&DATE(2026,8,31))+SUMIFS(Jumat!$H$7:$H$186,Jumat!$C$7:$C$186,$B5,Jumat!$A$7:$A$186,">="&DATE(2026,8,1),Jumat!$A$7:$A$186,"<="&DATE(2026,8,31)) -> 0 | G5: =SUMIFS(Senin!$H$7:$H$146,Senin!$C$7:$C$146,$B5,Senin!$A$7:$A$146,">="&DATE(2026,9,1),Senin!$A$7:$A$146,"<="&DATE(2026,9,30))+SUMIFS(Selasa!$H$7:$H$166,Selasa!$C$7:$C$166,$B5,Selasa!$A$7:$A$166,">="&DATE(2026,9,1),Selasa!$A$7:$A$166,"<="&DATE(2026,9,30))+SUMIFS(Rabu!$H$7:$H$206,Rabu!$C$7:$C$206,$B5,Rabu!$A$7:$A$206,">="&DATE(2026,9,1),Rabu!$A$7:$A$206,"<="&DATE(2026,9,30))+SUMIFS(Kamis!$H$7:$H$186,Kamis!$C$7:$C$186,$B5,Kamis!$A$7:$A$186,">="&DATE(2026,9,1),Kamis!$A$7:$A$186,"<="&DATE(2026,9,30))+SUMIFS(Jumat!$H$7:$H$186,Jumat!$C$7:$C$186,$B5,Jumat!$A$7:$A$186,">="&DATE(2026,9,1),Jumat!$A$7:$A$186,"<="&DATE(2026,9,30)) -> 0 | H5: =SUMIFS(Senin!$H$7:$H$146,Senin!$C$7:$C$146,$B5,Senin!$A$7:$A$146,">="&DATE(2026,10,1),Senin!$A$7:$A$146,"<="&DATE(2026,10,31))+SUMIFS(Selasa!$H$7:$H$166,Selasa!$C$7:$C$166,$B5,Selasa!$A$7:$A$166,">="&DATE(2026,10,1),Selasa!$A$7:$A$166,"<="&DATE(2026,10,31))+SUMIFS(Rabu!$H$7:$H$206,Rabu!$C$7:$C$206,$B5,Rabu!$A$7:$A$206,">="&DATE(2026,10,1),Rabu!$A$7:$A$206,"<="&DATE(2026,10,31))+SUMIFS(Kamis!$H$7:$H$186,Kamis!$C$7:$C$186,$B5,Kamis!$A$7:$A$186,">="&DATE(2026,10,1),Kamis!$A$7:$A$186,"<="&DATE(2026,10,31))+SUMIFS(Jumat!$H$7:$H$186,Jumat!$C$7:$C$186,$B5,Jumat!$A$7:$A$186,">="&DATE(2026,10,1),Jumat!$A$7:$A$186,"<="&DATE(2026,10,31)) -> 0 | I5: =SUMIFS(Senin!$H$7:$H$146,Senin!$C$7:$C$146,$B5,Senin!$A$7:$A$146,">="&DATE(2026,11,1),Senin!$A$7:$A$146,"<="&DATE(2026,11,30))+SUMIFS(Selasa!$H$7:$H$166,Selasa!$C$7:$C$166,$B5,Selasa!$A$7:$A$166,">="&DATE(2026,11,1),Selasa!$A$7:$A$166,"<="&DATE(2026,11,30))+SUMIFS(Rabu!$H$7:$H$206,Rabu!$C$7:$C$206,$B5,Rabu!$A$7:$A$206,">="&DATE(2026,11,1),Rabu!$A$7:$A$206,"<="&DATE(2026,11,30))+SUMIFS(Kamis!$H$7:$H$186,Kamis!$C$7:$C$186,$B5,Kamis!$A$7:$A$186,">="&DATE(2026,11,1),Kamis!$A$7:$A$186,"<="&DATE(2026,11,30))+SUMIFS(Jumat!$H$7:$H$186,Jumat!$C$7:$C$186,$B5,Jumat!$A$7:$A$186,">="&DATE(2026,11,1),Jumat!$A$7:$A$186,"<="&DATE(2026,11,30)) -> 0 | J5: =SUMIFS(Senin!$H$7:$H$146,Senin!$C$7:$C$146,$B5,Senin!$A$7:$A$146,">="&DATE(2026,12,1),Senin!$A$7:$A$146,"<="&DATE(2026,12,31))+SUMIFS(Selasa!$H$7:$H$166,Selasa!$C$7:$C$166,$B5,Selasa!$A$7:$A$166,">="&DATE(2026,12,1),Selasa!$A$7:$A$166,"<="&DATE(2026,12,31))+SUMIFS(Rabu!$H$7:$H$206,Rabu!$C$7:$C$206,$B5,Rabu!$A$7:$A$206,">="&DATE(2026,12,1),Rabu!$A$7:$A$206,"<="&DATE(2026,12,31))+SUMIFS(Kamis!$H$7:$H$186,Kamis!$C$7:$C$186,$B5,Kamis!$A$7:$A$186,">="&DATE(2026,12,1),Kamis!$A$7:$A$186,"<="&DATE(2026,12,31))+SUMIFS(Jumat!$H$7:$H$186,Jumat!$C$7:$C$186,$B5,Jumat!$A$7:$A$186,">="&DATE(2026,12,1),Jumat!$A$7:$A$186,"<="&DATE(2026,12,31)) -> 0 | K5: =SUMIFS(Senin!$H$7:$H$146,Senin!$C$7:$C$146,$B5,Senin!$A$7:$A$146,">="&DATE(2026,8,31),Senin!$A$7:$A$146,"<="&DATE(2026,9,6))+SUMIFS(Selasa!$H$7:$H$166,Selasa!$C$7:$C$166,$B5,Selasa!$A$7:$A$166,">="&DATE(2026,8,31),Selasa!$A$7:$A$166,"<="&DATE(2026,9,6))+SUMIFS(Rabu!$H$7:$H$206,Rabu!$C$7:$C$206,$B5,Rabu!$A$7:$A$206,">="&DATE(2026,8,31),Rabu!$A$7:$A$206,"<="&DATE(2026,9,6))+SUMIFS(Kamis!$H$7:$H$186,Kamis!$C$7:$C$186,$B5,Kamis!$A$7:$A$186,">="&DATE(2026,8,31),Kamis!$A$7:$A$186,"<="&DATE(2026,9,6))+SUMIFS(Jumat!$H$7:$H$186,Jumat!$C$7:$C$186,$B5,Jumat!$A$7:$A$186,">="&DATE(2026,8,31),Jumat!$A$7:$A$186,"<="&DATE(2026,9,6)) -> 0 | L5: =SUMIFS(Senin!$H$7:$H$146,Senin!$C$7:$C$146,$B5,Senin!$A$7:$A$146,">="&DATE(2026,9,7),Senin!$A$7:$A$146,"<="&DATE(2026,9,13))+SUMIFS(Selasa!$H$7:$H$166,Selasa!$C$7:$C$166,$B5,Selasa!$A$7:$A$166,">="&DATE(2026,9,7),Selasa!$A$7:$A$166,"<="&DATE(2026,9,13))+SUMIFS(Rabu!$H$7:$H$206,Rabu!$C$7:$C$206,$B5,Rabu!$A$7:$A$206,">="&DATE(2026,9,7),Rabu!$A$7:$A$206,"<="&DATE(2026,9,13))+SUMIFS(Kamis!$H$7:$H$186,Kamis!$C$7:$C$186,$B5,Kamis!$A$7:$A$186,">="&DATE(2026,9,7),Kamis!$A$7:$A$186,"<="&DATE(2026,9,13))+SUMIFS(Jumat!$H$7:$H$186,Jumat!$C$7:$C$186,$B5,Jumat!$A$7:$A$186,">="&DATE(2026,9,7),Jumat!$A$7:$A$186,"<="&DATE(2026,9,13)) -> 0 | M5: =SUMIFS(Senin!$H$7:$H$146,Senin!$C$7:$C$146,$B5,Senin!$A$7:$A$146,">="&DATE(2026,9,14),Senin!$A$7:$A$146,"<="&DATE(2026,9,20))+SUMIFS(Selasa!$H$7:$H$166,Selasa!$C$7:$C$166,$B5,Selasa!$A$7:$A$166,">="&DATE(2026,9,14),Selasa!$A$7:$A$166,"<="&DATE(2026,9,20))+SUMIFS(Rabu!$H$7:$H$206,Rabu!$C$7:$C$206,$B5,Rabu!$A$7:$A$206,">="&DATE(2026,9,14),Rabu!$A$7:$A$206,"<="&DATE(2026,9,20))+SUMIFS(Kamis!$H$7:$H$186,Kamis!$C$7:$C$186,$B5,Kamis!$A$7:$A$186,">="&DATE(2026,9,14),Kamis!$A$7:$A$186,"<="&DATE(2026,9,20))+SUMIFS(Jumat!$H$7:$H$186,Jumat!$C$7:$C$186,$B5,Jumat!$A$7:$A$186,">="&DATE(2026,9,14),Jumat!$A$7:$A$186,"<="&DATE(2026,9,20)) -> 0 | N5: =SUMIFS(Senin!$H$7:$H$146,Senin!$C$7:$C$146,$B5,Senin!$A$7:$A$146,">="&DATE(2026,9,21),Senin!$A$7:$A$146,"<="&DATE(2026,9,27))+SUMIFS(Selasa!$H$7:$H$166,Selasa!$C$7:$C$166,$B5,Selasa!$A$7:$A$166,">="&DATE(2026,9,21),Selasa!$A$7:$A$166,"<="&DATE(2026,9,27))+SUMIFS(Rabu!$H$7:$H$206,Rabu!$C$7:$C$206,$B5,Rabu!$A$7:$A$206,">="&DATE(2026,9,21),Rabu!$A$7:$A$206,"<="&DATE(2026,9,27))+SUMIFS(Kamis!$H$7:$H$186,Kamis!$C$7:$C$186,$B5,Kamis!$A$7:$A$186,">="&DATE(2026,9,21),Kamis!$A$7:$A$186,"<="&DATE(2026,9,27))+SUMIFS(Jumat!$H$7:$H$186,Jumat!$C$7:$C$186,$B5,Jumat!$A$7:$A$186,">="&DATE(2026,9,21),Jumat!$A$7:$A$186,"<="&DATE(2026,9,27)) -> 0 | O5: =SUMIFS(Senin!$H$7:$H$146,Senin!$C$7:$C$146,$B5,Senin!$A$7:$A$146,">="&DATE(2026,9,28),Senin!$A$7:$A$146,"<="&DATE(2026,10,4))+SUMIFS(Selasa!$H$7:$H$166,Selasa!$C$7:$C$166,$B5,Selasa!$A$7:$A$166,">="&DATE(2026,9,28),Selasa!$A$7:$A$166,"<="&DATE(2026,10,4))+SUMIFS(Rabu!$H$7:$H$206,Rabu!$C$7:$C$206,$B5,Rabu!$A$7:$A$206,">="&DATE(2026,9,28),Rabu!$A$7:$A$206,"<="&DATE(2026,10,4))+SUMIFS(Kamis!$H$7:$H$186,Kamis!$C$7:$C$186,$B5,Kamis!$A$7:$A$186,">="&DATE(2026,9,28),Kamis!$A$7:$A$186,"<="&DATE(2026,10,4))+SUMIFS(Jumat!$H$7:$H$186,Jumat!$C$7:$C$186,$B5,Jumat!$A$7:$A$186,">="&DATE(2026,9,28),Jumat!$A$7:$A$186,"<="&DATE(2026,10,4)) -> 0 | P5: =SUMIFS(Senin!$H$7:$H$146,Senin!$C$7:$C$146,$B5,Senin!$A$7:$A$146,">="&DATE(2026,10,5),Senin!$A$7:$A$146,"<="&DATE(2026,10,11))+SUMIFS(Selasa!$H$7:$H$166,Selasa!$C$7:$C$166,$B5,Selasa!$A$7:$A$166,">="&DATE(2026,10,5),Selasa!$A$7:$A$166,"<="&DATE(2026,10,11))+SUMIFS(Rabu!$H$7:$H$206,Rabu!$C$7:$C$206,$B5,Rabu!$A$7:$A$206,">="&DATE(2026,10,5),Rabu!$A$7:$A$206,"<="&DATE(2026,10,11))+SUMIFS(Kamis!$H$7:$H$186,Kamis!$C$7:$C$186,$B5,Kamis!$A$7:$A$186,">="&DATE(2026,10,5),Kamis!$A$7:$A$186,"<="&DATE(2026,10,11))+SUMIFS(Jumat!$H$7:$H$186,Jumat!$C$7:$C$186,$B5,Jumat!$A$7:$A$186,">="&DATE(2026,10,5),Jumat!$A$7:$A$186,"<="&DATE(2026,10,11)) -> 0 | Q5: =SUMIFS(Senin!$H$7:$H$146,Senin!$C$7:$C$146,$B5,Senin!$A$7:$A$146,">="&DATE(2026,10,12),Senin!$A$7:$A$146,"<="&DATE(2026,10,18))+SUMIFS(Selasa!$H$7:$H$166,Selasa!$C$7:$C$166,$B5,Selasa!$A$7:$A$166,">="&DATE(2026,10,12),Selasa!$A$7:$A$166,"<="&DATE(2026,10,18))+SUMIFS(Rabu!$H$7:$H$206,Rabu!$C$7:$C$206,$B5,Rabu!$A$7:$A$206,">="&DATE(2026,10,12),Rabu!$A$7:$A$206,"<="&DATE(2026,10,18))+SUMIFS(Kamis!$H$7:$H$186,Kamis!$C$7:$C$186,$B5,Kamis!$A$7:$A$186,">="&DATE(2026,10,12),Kamis!$A$7:$A$186,"<="&DATE(2026,10,18))+SUMIFS(Jumat!$H$7:$H$186,Jumat!$C$7:$C$186,$B5,Jumat!$A$7:$A$186,">="&DATE(2026,10,12),Jumat!$A$7:$A$186,"<="&DATE(2026,10,18)) -> 0 | R5: =SUMIFS(Senin!$H$7:$H$146,Senin!$C$7:$C$146,$B5,Senin!$A$7:$A$146,">="&DATE(2026,10,19),Senin!$A$7:$A$146,"<="&DATE(2026,10,25))+SUMIFS(Selasa!$H$7:$H$166,Selasa!$C$7:$C$166,$B5,Selasa!$A$7:$A$166,">="&DATE(2026,10,19),Selasa!$A$7:$A$166,"<="&DATE(2026,10,25))+SUMIFS(Rabu!$H$7:$H$206,Rabu!$C$7:$C$206,$B5,Rabu!$A$7:$A$206,">="&DATE(2026,10,19),Rabu!$A$7:$A$206,"<="&DATE(2026,10,25))+SUMIFS(Kamis!$H$7:$H$186,Kamis!$C$7:$C$186,$B5,Kamis!$A$7:$A$186,">="&DATE(2026,10,19),Kamis!$A$7:$A$186,"<="&DATE(2026,10,25))+SUMIFS(Jumat!$H$7:$H$186,Jumat!$C$7:$C$186,$B5,Jumat!$A$7:$A$186,">="&DATE(2026,10,19),Jumat!$A$7:$A$186,"<="&DATE(2026,10,25)) -> 0 | S5: =SUMIFS(Senin!$H$7:$H$146,Senin!$C$7:$C$146,$B5,Senin!$A$7:$A$146,">="&DATE(2026,10,26),Senin!$A$7:$A$146,"<="&DATE(2026,11,1))+SUMIFS(Selasa!$H$7:$H$166,Selasa!$C$7:$C$166,$B5,Selasa!$A$7:$A$166,">="&DATE(2026,10,26),Selasa!$A$7:$A$166,"<="&DATE(2026,11,1))+SUMIFS(Rabu!$H$7:$H$206,Rabu!$C$7:$C$206,$B5,Rabu!$A$7:$A$206,">="&DATE(2026,10,26),Rabu!$A$7:$A$206,"<="&DATE(2026,11,1))+SUMIFS(Kamis!$H$7:$H$186,Kamis!$C$7:$C$186,$B5,Kamis!$A$7:$A$186,">="&DATE(2026,10,26),Kamis!$A$7:$A$186,"<="&DATE(2026,11,1))+SUMIFS(Jumat!$H$7:$H$186,Jumat!$C$7:$C$186,$B5,Jumat!$A$7:$A$186,">="&DATE(2026,10,26),Jumat!$A$7:$A$186,"<="&DATE(2026,11,1)) -> 0 | T5: =SUMIFS(Senin!$H$7:$H$146,Senin!$C$7:$C$146,$B5,Senin!$A$7:$A$146,">="&DATE(2026,11,2),Senin!$A$7:$A$146,"<="&DATE(2026,11,8))+SUMIFS(Selasa!$H$7:$H$166,Selasa!$C$7:$C$166,$B5,Selasa!$A$7:$A$166,">="&DATE(2026,11,2),Selasa!$A$7:$A$166,"<="&DATE(2026,11,8))+SUMIFS(Rabu!$H$7:$H$206,Rabu!$C$7:$C$206,$B5,Rabu!$A$7:$A$206,">="&DATE(2026,11,2),Rabu!$A$7:$A$206,"<="&DATE(2026,11,8))+SUMIFS(Kamis!$H$7:$H$186,Kamis!$C$7:$C$186,$B5,Kamis!$A$7:$A$186,">="&DATE(2026,11,2),Kamis!$A$7:$A$186,"<="&DATE(2026,11,8))+SUMIFS(Jumat!$H$7:$H$186,Jumat!$C$7:$C$186,$B5,Jumat!$A$7:$A$186,">="&DATE(2026,11,2),Jumat!$A$7:$A$186,"<="&DATE(2026,11,8)) -> 0 | U5: =SUMIFS(Senin!$H$7:$H$146,Senin!$C$7:$C$146,$B5,Senin!$A$7:$A$146,">="&DATE(2026,11,9),Senin!$A$7:$A$146,"<="&DATE(2026,11,15))+SUMIFS(Selasa!$H$7:$H$166,Selasa!$C$7:$C$166,$B5,Selasa!$A$7:$A$166,">="&DATE(2026,11,9),Selasa!$A$7:$A$166,"<="&DATE(2026,11,15))+SUMIFS(Rabu!$H$7:$H$206,Rabu!$C$7:$C$206,$B5,Rabu!$A$7:$A$206,">="&DATE(2026,11,9),Rabu!$A$7:$A$206,"<="&DATE(2026,11,15))+SUMIFS(Kamis!$H$7:$H$186,Kamis!$C$7:$C$186,$B5,Kamis!$A$7:$A$186,">="&DATE(2026,11,9),Kamis!$A$7:$A$186,"<="&DATE(2026,11,15))+SUMIFS(Jumat!$H$7:$H$186,Jumat!$C$7:$C$186,$B5,Jumat!$A$7:$A$186,">="&DATE(2026,11,9),Jumat!$A$7:$A$186,"<="&DATE(2026,11,15)) -> 0 | V5: =SUMIFS(Senin!$H$7:$H$146,Senin!$C$7:$C$146,$B5,Senin!$A$7:$A$146,">="&DATE(2026,11,16),Senin!$A$7:$A$146,"<="&DATE(2026,11,22))+SUMIFS(Selasa!$H$7:$H$166,Selasa!$C$7:$C$166,$B5,Selasa!$A$7:$A$166,">="&DATE(2026,11,16),Selasa!$A$7:$A$166,"<="&DATE(2026,11,22))+SUMIFS(Rabu!$H$7:$H$206,Rabu!$C$7:$C$206,$B5,Rabu!$A$7:$A$206,">="&DATE(2026,11,16),Rabu!$A$7:$A$206,"<="&DATE(2026,11,22))+SUMIFS(Kamis!$H$7:$H$186,Kamis!$C$7:$C$186,$B5,Kamis!$A$7:$A$186,">="&DATE(2026,11,16),Kamis!$A$7:$A$186,"<="&DATE(2026,11,22))+SUMIFS(Jumat!$H$7:$H$186,Jumat!$C$7:$C$186,$B5,Jumat!$A$7:$A$186,">="&DATE(2026,11,16),Jumat!$A$7:$A$186,"<="&DATE(2026,11,22)) -> 0 | W5: =SUMIFS(Senin!$H$7:$H$146,Senin!$C$7:$C$146,$B5,Senin!$A$7:$A$146,">="&DATE(2026,11,23),Senin!$A$7:$A$146,"<="&DATE(2026,11,29))+SUMIFS(Selasa!$H$7:$H$166,Selasa!$C$7:$C$166,$B5,Selasa!$A$7:$A$166,">="&DATE(2026,11,23),Selasa!$A$7:$A$166,"<="&DATE(2026,11,29))+SUMIFS(Rabu!$H$7:$H$206,Rabu!$C$7:$C$206,$B5,Rabu!$A$7:$A$206,">="&DATE(2026,11,23),Rabu!$A$7:$A$206,"<="&DATE(2026,11,29))+SUMIFS(Kamis!$H$7:$H$186,Kamis!$C$7:$C$186,$B5,Kamis!$A$7:$A$186,">="&DATE(2026,11,23),Kamis!$A$7:$A$186,"<="&DATE(2026,11,29))+SUMIFS(Jumat!$H$7:$H$186,Jumat!$C$7:$C$186,$B5,Jumat!$A$7:$A$186,">="&DATE(2026,11,23),Jumat!$A$7:$A$186,"<="&DATE(2026,11,29)) -> 0 | X5: =SUMIFS(Senin!$H$7:$H$146,Senin!$C$7:$C$146,$B5,Senin!$A$7:$A$146,">="&DATE(2026,11,30),Senin!$A$7:$A$146,"<="&DATE(2026,12,6))+SUMIFS(Selasa!$H$7:$H$166,Selasa!$C$7:$C$166,$B5,Selasa!$A$7:$A$166,">="&DATE(2026,11,30),Selasa!$A$7:$A$166,"<="&DATE(2026,12,6))+SUMIFS(Rabu!$H$7:$H$206,Rabu!$C$7:$C$206,$B5,Rabu!$A$7:$A$206,">="&DATE(2026,11,30),Rabu!$A$7:$A$206,"<="&DATE(2026,12,6))+SUMIFS(Kamis!$H$7:$H$186,Kamis!$C$7:$C$186,$B5,Kamis!$A$7:$A$186,">="&DATE(2026,11,30),Kamis!$A$7:$A$186,"<="&DATE(2026,12,6))+SUMIFS(Jumat!$H$7:$H$186,Jumat!$C$7:$C$186,$B5,Jumat!$A$7:$A$186,">="&DATE(2026,11,30),Jumat!$A$7:$A$186,"<="&DATE(2026,12,6)) -> 0 | Y5: =SUMIFS(Senin!$H$7:$H$146,Senin!$C$7:$C$146,$B5,Senin!$A$7:$A$146,">="&DATE(2026,12,7),Senin!$A$7:$A$146,"<="&DATE(2026,12,13))+SUMIFS(Selasa!$H$7:$H$166,Selasa!$C$7:$C$166,$B5,Selasa!$A$7:$A$166,">="&DATE(2026,12,7),Selasa!$A$7:$A$166,"<="&DATE(2026,12,13))+SUMIFS(Rabu!$H$7:$H$206,Rabu!$C$7:$C$206,$B5,Rabu!$A$7:$A$206,">="&DATE(2026,12,7),Rabu!$A$7:$A$206,"<="&DATE(2026,12,13))+SUMIFS(Kamis!$H$7:$H$186,Kamis!$C$7:$C$186,$B5,Kamis!$A$7:$A$186,">="&DATE(2026,12,7),Kamis!$A$7:$A$186,"<="&DATE(2026,12,13))+SUMIFS(Jumat!$H$7:$H$186,Jumat!$C$7:$C$186,$B5,Jumat!$A$7:$A$186,">="&DATE(2026,12,7),Jumat!$A$7:$A$186,"<="&DATE(2026,12,13)) -> 0 | Z5: =SUMIFS(Senin!$H$7:$H$146,Senin!$C$7:$C$146,$B5,Senin!$A$7:$A$146,">="&DATE(2026,12,14),Senin!$A$7:$A$146,"<="&DATE(2026,12,20))+SUMIFS(Selasa!$H$7:$H$166,Selasa!$C$7:$C$166,$B5,Selasa!$A$7:$A$166,">="&DATE(2026,12,14),Selasa!$A$7:$A$166,"<="&DATE(2026,12,20))+SUMIFS(Rabu!$H$7:$H$206,Rabu!$C$7:$C$206,$B5,Rabu!$A$7:$A$206,">="&DATE(2026,12,14),Rabu!$A$7:$A$206,"<="&DATE(2026,12,20))+SUMIFS(Kamis!$H$7:$H$186,Kamis!$C$7:$C$186,$B5,Kamis!$A$7:$A$186,">="&DATE(2026,12,14),Kamis!$A$7:$A$186,"<="&DATE(2026,12,20))+SUMIFS(Jumat!$H$7:$H$186,Jumat!$C$7:$C$186,$B5,Jumat!$A$7:$A$186,">="&DATE(2026,12,14),Jumat!$A$7:$A$186,"<="&DATE(2026,12,20)) -> 0 | AA5: =SUMIFS(Senin!$H$7:$H$146,Senin!$C$7:$C$146,$B5,Senin!$A$7:$A$146,">="&DATE(2026,12,21),Senin!$A$7:$A$146,"<="&DATE(2026,12,27))+SUMIFS(Selasa!$H$7:$H$166,Selasa!$C$7:$C$166,$B5,Selasa!$A$7:$A$166,">="&DATE(2026,12,21),Selasa!$A$7:$A$166,"<="&DATE(2026,12,27))+SUMIFS(Rabu!$H$7:$H$206,Rabu!$C$7:$C$206,$B5,Rabu!$A$7:$A$206,">="&DATE(2026,12,21),Rabu!$A$7:$A$206,"<="&DATE(2026,12,27))+SUMIFS(Kamis!$H$7:$H$186,Kamis!$C$7:$C$186,$B5,Kamis!$A$7:$A$186,">="&DATE(2026,12,21),Kamis!$A$7:$A$186,"<="&DATE(2026,12,27))+SUMIFS(Jumat!$H$7:$H$186,Jumat!$C$7:$C$186,$B5,Jumat!$A$7:$A$186,">="&DATE(2026,12,21),Jumat!$A$7:$A$186,"<="&DATE(2026,12,27)) -> 0 | AB5: =SUMIFS(Senin!$H$7:$H$146,Senin!$C$7:$C$146,$B5,Senin!$A$7:$A$146,">="&DATE(2026,12,28),Senin!$A$7:$A$146,"<="&DATE(2027,1,3))+SUMIFS(Selasa!$H$7:$H$166,Selasa!$C$7:$C$166,$B5,Selasa!$A$7:$A$166,">="&DATE(2026,12,28),Selasa!$A$7:$A$166,"<="&DATE(2027,1,3))+SUMIFS(Rabu!$H$7:$H$206,Rabu!$C$7:$C$206,$B5,Rabu!$A$7:$A$206,">="&DATE(2026,12,28),Rabu!$A$7:$A$206,"<="&DATE(2027,1,3))+SUMIFS(Kamis!$H$7:$H$186,Kamis!$C$7:$C$186,$B5,Kamis!$A$7:$A$186,">="&DATE(2026,12,28),Kamis!$A$7:$A$186,"<="&DATE(2027,1,3))+SUMIFS(Jumat!$H$7:$H$186,Jumat!$C$7:$C$186,$B5,Jumat!$A$7:$A$186,">="&DATE(2026,12,28),Jumat!$A$7:$A$186,"<="&DATE(2027,1,3)) -> 0 | AC5: =SUMIFS(Senin!$H$7:$H$146,Senin!$C$7:$C$146,$B5,Senin!$A$7:$A$146,">="&DATE(2027,1,4),Senin!$A$7:$A$146,"<="&DATE(2027,1,10))+SUMIFS(Selasa!$H$7:$H$166,Selasa!$C$7:$C$166,$B5,Selasa!$A$7:$A$166,">="&DATE(2027,1,4),Selasa!$A$7:$A$166,"<="&DATE(2027,1,10))+SUMIFS(Rabu!$H$7:$H$206,Rabu!$C$7:$C$206,$B5,Rabu!$A$7:$A$206,">="&DATE(2027,1,4),Rabu!$A$7:$A$206,"<="&DATE(2027,1,10))+SUMIFS(Kamis!$H$7:$H$186,Kamis!$C$7:$C$186,$B5,Kamis!$A$7:$A$186,">="&DATE(2027,1,4),Kamis!$A$7:$A$186,"<="&DATE(2027,1,10))+SUMIFS(Jumat!$H$7:$H$186,Jumat!$C$7:$C$186,$B5,Jumat!$A$7:$A$186,">="&DATE(2027,1,4),Jumat!$A$7:$A$186,"<="&DATE(2027,1,10)) -> 0 | AD5: =SUMIFS(Senin!$H$7:$H$146,Senin!$C$7:$C$146,$B5,Senin!$A$7:$A$146,">="&DATE(2027,1,11),Senin!$A$7:$A$146,"<="&DATE(2027,1,17))+SUMIFS(Selasa!$H$7:$H$166,Selasa!$C$7:$C$166,$B5,Selasa!$A$7:$A$166,">="&DATE(2027,1,11),Selasa!$A$7:$A$166,"<="&DATE(2027,1,17))+SUMIFS(Rabu!$H$7:$H$206,Rabu!$C$7:$C$206,$B5,Rabu!$A$7:$A$206,">="&DATE(2027,1,11),Rabu!$A$7:$A$206,"<="&DATE(2027,1,17))+SUMIFS(Kamis!$H$7:$H$186,Kamis!$C$7:$C$186,$B5,Kamis!$A$7:$A$186,">="&DATE(2027,1,11),Kamis!$A$7:$A$186,"<="&DATE(2027,1,17))+SUMIFS(Jumat!$H$7:$H$186,Jumat!$C$7:$C$186,$B5,Jumat!$A$7:$A$186,">="&DATE(2027,1,11),Jumat!$A$7:$A$186,"<="&DATE(2027,1,17)) -> 0
A6: 3 | B6: Taslim Ismail Anshorullah | C6: =COUNTIFS(Senin!$C$7:$C$146,$B6,Senin!$G$7:$G$146,"Ya",Senin!$E$7:$E$146,"<>")+COUNTIFS(Selasa!$C$7:$C$166,$B6,Selasa!$G$7:$G$166,"Ya",Selasa!$E$7:$E$166,"<>")+COUNTIFS(Rabu!$C$7:$C$206,$B6,Rabu!$G$7:$G$206,"Ya",Rabu!$E$7:$E$206,"<>")+COUNTIFS(Kamis!$C$7:$C$186,$B6,Kamis!$G$7:$G$186,"Ya",Kamis!$E$7:$E$186,"<>")+COUNTIFS(Jumat!$C$7:$C$186,$B6,Jumat!$G$7:$G$186,"Ya",Jumat!$E$7:$E$186,"<>") -> 0 | D6: =COUNTIFS(Senin!$C$7:$C$146,$B6,Senin!$G$7:$G$146,"Ya",Senin!$E$7:$E$146,"")+COUNTIFS(Selasa!$C$7:$C$166,$B6,Selasa!$G$7:$G$166,"Ya",Selasa!$E$7:$E$166,"")+COUNTIFS(Rabu!$C$7:$C$206,$B6,Rabu!$G$7:$G$206,"Ya",Rabu!$E$7:$E$206,"")+COUNTIFS(Kamis!$C$7:$C$186,$B6,Kamis!$G$7:$G$186,"Ya",Kamis!$E$7:$E$186,"")+COUNTIFS(Jumat!$C$7:$C$186,$B6,Jumat!$G$7:$G$186,"Ya",Jumat!$E$7:$E$186,"") -> 0 | E6: =SUMIFS(Senin!$H$7:$H$146,Senin!$C$7:$C$146,$B6,Senin!$A$7:$A$146,">="&DATE(2026,8,1),Senin!$A$7:$A$146,"<="&DATE(2026,12,31))+SUMIFS(Selasa!$H$7:$H$166,Selasa!$C$7:$C$166,$B6,Selasa!$A$7:$A$166,">="&DATE(2026,8,1),Selasa!$A$7:$A$166,"<="&DATE(2026,12,31))+SUMIFS(Rabu!$H$7:$H$206,Rabu!$C$7:$C$206,$B6,Rabu!$A$7:$A$206,">="&DATE(2026,8,1),Rabu!$A$7:$A$206,"<="&DATE(2026,12,31))+SUMIFS(Kamis!$H$7:$H$186,Kamis!$C$7:$C$186,$B6,Kamis!$A$7:$A$186,">="&DATE(2026,8,1),Kamis!$A$7:$A$186,"<="&DATE(2026,12,31))+SUMIFS(Jumat!$H$7:$H$186,Jumat!$C$7:$C$186,$B6,Jumat!$A$7:$A$186,">="&DATE(2026,8,1),Jumat!$A$7:$A$186,"<="&DATE(2026,12,31)) -> 0 | F6: =SUMIFS(Senin!$H$7:$H$146,Senin!$C$7:$C$146,$B6,Senin!$A$7:$A$146,">="&DATE(2026,8,1),Senin!$A$7:$A$146,"<="&DATE(2026,8,31))+SUMIFS(Selasa!$H$7:$H$166,Selasa!$C$7:$C$166,$B6,Selasa!$A$7:$A$166,">="&DATE(2026,8,1),Selasa!$A$7:$A$166,"<="&DATE(2026,8,31))+SUMIFS(Rabu!$H$7:$H$206,Rabu!$C$7:$C$206,$B6,Rabu!$A$7:$A$206,">="&DATE(2026,8,1),Rabu!$A$7:$A$206,"<="&DATE(2026,8,31))+SUMIFS(Kamis!$H$7:$H$186,Kamis!$C$7:$C$186,$B6,Kamis!$A$7:$A$186,">="&DATE(2026,8,1),Kamis!$A$7:$A$186,"<="&DATE(2026,8,31))+SUMIFS(Jumat!$H$7:$H$186,Jumat!$C$7:$C$186,$B6,Jumat!$A$7:$A$186,">="&DATE(2026,8,1),Jumat!$A$7:$A$186,"<="&DATE(2026,8,31)) -> 0 | G6: =SUMIFS(Senin!$H$7:$H$146,Senin!$C$7:$C$146,$B6,Senin!$A$7:$A$146,">="&DATE(2026,9,1),Senin!$A$7:$A$146,"<="&DATE(2026,9,30))+SUMIFS(Selasa!$H$7:$H$166,Selasa!$C$7:$C$166,$B6,Selasa!$A$7:$A$166,">="&DATE(2026,9,1),Selasa!$A$7:$A$166,"<="&DATE(2026,9,30))+SUMIFS(Rabu!$H$7:$H$206,Rabu!$C$7:$C$206,$B6,Rabu!$A$7:$A$206,">="&DATE(2026,9,1),Rabu!$A$7:$A$206,"<="&DATE(2026,9,30))+SUMIFS(Kamis!$H$7:$H$186,Kamis!$C$7:$C$186,$B6,Kamis!$A$7:$A$186,">="&DATE(2026,9,1),Kamis!$A$7:$A$186,"<="&DATE(2026,9,30))+SUMIFS(Jumat!$H$7:$H$186,Jumat!$C$7:$C$186,$B6,Jumat!$A$7:$A$186,">="&DATE(2026,9,1),Jumat!$A$7:$A$186,"<="&DATE(2026,9,30)) -> 0 | H6: =SUMIFS(Senin!$H$7:$H$146,Senin!$C$7:$C$146,$B6,Senin!$A$7:$A$146,">="&DATE(2026,10,1),Senin!$A$7:$A$146,"<="&DATE(2026,10,31))+SUMIFS(Selasa!$H$7:$H$166,Selasa!$C$7:$C$166,$B6,Selasa!$A$7:$A$166,">="&DATE(2026,10,1),Selasa!$A$7:$A$166,"<="&DATE(2026,10,31))+SUMIFS(Rabu!$H$7:$H$206,Rabu!$C$7:$C$206,$B6,Rabu!$A$7:$A$206,">="&DATE(2026,10,1),Rabu!$A$7:$A$206,"<="&DATE(2026,10,31))+SUMIFS(Kamis!$H$7:$H$186,Kamis!$C$7:$C$186,$B6,Kamis!$A$7:$A$186,">="&DATE(2026,10,1),Kamis!$A$7:$A$186,"<="&DATE(2026,10,31))+SUMIFS(Jumat!$H$7:$H$186,Jumat!$C$7:$C$186,$B6,Jumat!$A$7:$A$186,">="&DATE(2026,10,1),Jumat!$A$7:$A$186,"<="&DATE(2026,10,31)) -> 0 | I6: =SUMIFS(Senin!$H$7:$H$146,Senin!$C$7:$C$146,$B6,Senin!$A$7:$A$146,">="&DATE(2026,11,1),Senin!$A$7:$A$146,"<="&DATE(2026,11,30))+SUMIFS(Selasa!$H$7:$H$166,Selasa!$C$7:$C$166,$B6,Selasa!$A$7:$A$166,">="&DATE(2026,11,1),Selasa!$A$7:$A$166,"<="&DATE(2026,11,30))+SUMIFS(Rabu!$H$7:$H$206,Rabu!$C$7:$C$206,$B6,Rabu!$A$7:$A$206,">="&DATE(2026,11,1),Rabu!$A$7:$A$206,"<="&DATE(2026,11,30))+SUMIFS(Kamis!$H$7:$H$186,Kamis!$C$7:$C$186,$B6,Kamis!$A$7:$A$186,">="&DATE(2026,11,1),Kamis!$A$7:$A$186,"<="&DATE(2026,11,30))+SUMIFS(Jumat!$H$7:$H$186,Jumat!$C$7:$C$186,$B6,Jumat!$A$7:$A$186,">="&DATE(2026,11,1),Jumat!$A$7:$A$186,"<="&DATE(2026,11,30)) -> 0 | J6: =SUMIFS(Senin!$H$7:$H$146,Senin!$C$7:$C$146,$B6,Senin!$A$7:$A$146,">="&DATE(2026,12,1),Senin!$A$7:$A$146,"<="&DATE(2026,12,31))+SUMIFS(Selasa!$H$7:$H$166,Selasa!$C$7:$C$166,$B6,Selasa!$A$7:$A$166,">="&DATE(2026,12,1),Selasa!$A$7:$A$166,"<="&DATE(2026,12,31))+SUMIFS(Rabu!$H$7:$H$206,Rabu!$C$7:$C$206,$B6,Rabu!$A$7:$A$206,">="&DATE(2026,12,1),Rabu!$A$7:$A$206,"<="&DATE(2026,12,31))+SUMIFS(Kamis!$H$7:$H$186,Kamis!$C$7:$C$186,$B6,Kamis!$A$7:$A$186,">="&DATE(2026,12,1),Kamis!$A$7:$A$186,"<="&DATE(2026,12,31))+SUMIFS(Jumat!$H$7:$H$186,Jumat!$C$7:$C$186,$B6,Jumat!$A$7:$A$186,">="&DATE(2026,12,1),Jumat!$A$7:$A$186,"<="&DATE(2026,12,31)) -> 0 | K6: =SUMIFS(Senin!$H$7:$H$146,Senin!$C$7:$C$146,$B6,Senin!$A$7:$A$146,">="&DATE(2026,8,31),Senin!$A$7:$A$146,"<="&DATE(2026,9,6))+SUMIFS(Selasa!$H$7:$H$166,Selasa!$C$7:$C$166,$B6,Selasa!$A$7:$A$166,">="&DATE(2026,8,31),Selasa!$A$7:$A$166,"<="&DATE(2026,9,6))+SUMIFS(Rabu!$H$7:$H$206,Rabu!$C$7:$C$206,$B6,Rabu!$A$7:$A$206,">="&DATE(2026,8,31),Rabu!$A$7:$A$206,"<="&DATE(2026,9,6))+SUMIFS(Kamis!$H$7:$H$186,Kamis!$C$7:$C$186,$B6,Kamis!$A$7:$A$186,">="&DATE(2026,8,31),Kamis!$A$7:$A$186,"<="&DATE(2026,9,6))+SUMIFS(Jumat!$H$7:$H$186,Jumat!$C$7:$C$186,$B6,Jumat!$A$7:$A$186,">="&DATE(2026,8,31),Jumat!$A$7:$A$186,"<="&DATE(2026,9,6)) -> 0 | L6: =SUMIFS(Senin!$H$7:$H$146,Senin!$C$7:$C$146,$B6,Senin!$A$7:$A$146,">="&DATE(2026,9,7),Senin!$A$7:$A$146,"<="&DATE(2026,9,13))+SUMIFS(Selasa!$H$7:$H$166,Selasa!$C$7:$C$166,$B6,Selasa!$A$7:$A$166,">="&DATE(2026,9,7),Selasa!$A$7:$A$166,"<="&DATE(2026,9,13))+SUMIFS(Rabu!$H$7:$H$206,Rabu!$C$7:$C$206,$B6,Rabu!$A$7:$A$206,">="&DATE(2026,9,7),Rabu!$A$7:$A$206,"<="&DATE(2026,9,13))+SUMIFS(Kamis!$H$7:$H$186,Kamis!$C$7:$C$186,$B6,Kamis!$A$7:$A$186,">="&DATE(2026,9,7),Kamis!$A$7:$A$186,"<="&DATE(2026,9,13))+SUMIFS(Jumat!$H$7:$H$186,Jumat!$C$7:$C$186,$B6,Jumat!$A$7:$A$186,">="&DATE(2026,9,7),Jumat!$A$7:$A$186,"<="&DATE(2026,9,13)) -> 0 | M6: =SUMIFS(Senin!$H$7:$H$146,Senin!$C$7:$C$146,$B6,Senin!$A$7:$A$146,">="&DATE(2026,9,14),Senin!$A$7:$A$146,"<="&DATE(2026,9,20))+SUMIFS(Selasa!$H$7:$H$166,Selasa!$C$7:$C$166,$B6,Selasa!$A$7:$A$166,">="&DATE(2026,9,14),Selasa!$A$7:$A$166,"<="&DATE(2026,9,20))+SUMIFS(Rabu!$H$7:$H$206,Rabu!$C$7:$C$206,$B6,Rabu!$A$7:$A$206,">="&DATE(2026,9,14),Rabu!$A$7:$A$206,"<="&DATE(2026,9,20))+SUMIFS(Kamis!$H$7:$H$186,Kamis!$C$7:$C$186,$B6,Kamis!$A$7:$A$186,">="&DATE(2026,9,14),Kamis!$A$7:$A$186,"<="&DATE(2026,9,20))+SUMIFS(Jumat!$H$7:$H$186,Jumat!$C$7:$C$186,$B6,Jumat!$A$7:$A$186,">="&DATE(2026,9,14),Jumat!$A$7:$A$186,"<="&DATE(2026,9,20)) -> 0 | N6: =SUMIFS(Senin!$H$7:$H$146,Senin!$C$7:$C$146,$B6,Senin!$A$7:$A$146,">="&DATE(2026,9,21),Senin!$A$7:$A$146,"<="&DATE(2026,9,27))+SUMIFS(Selasa!$H$7:$H$166,Selasa!$C$7:$C$166,$B6,Selasa!$A$7:$A$166,">="&DATE(2026,9,21),Selasa!$A$7:$A$166,"<="&DATE(2026,9,27))+SUMIFS(Rabu!$H$7:$H$206,Rabu!$C$7:$C$206,$B6,Rabu!$A$7:$A$206,">="&DATE(2026,9,21),Rabu!$A$7:$A$206,"<="&DATE(2026,9,27))+SUMIFS(Kamis!$H$7:$H$186,Kamis!$C$7:$C$186,$B6,Kamis!$A$7:$A$186,">="&DATE(2026,9,21),Kamis!$A$7:$A$186,"<="&DATE(2026,9,27))+SUMIFS(Jumat!$H$7:$H$186,Jumat!$C$7:$C$186,$B6,Jumat!$A$7:$A$186,">="&DATE(2026,9,21),Jumat!$A$7:$A$186,"<="&DATE(2026,9,27)) -> 0 | O6: =SUMIFS(Senin!$H$7:$H$146,Senin!$C$7:$C$146,$B6,Senin!$A$7:$A$146,">="&DATE(2026,9,28),Senin!$A$7:$A$146,"<="&DATE(2026,10,4))+SUMIFS(Selasa!$H$7:$H$166,Selasa!$C$7:$C$166,$B6,Selasa!$A$7:$A$166,">="&DATE(2026,9,28),Selasa!$A$7:$A$166,"<="&DATE(2026,10,4))+SUMIFS(Rabu!$H$7:$H$206,Rabu!$C$7:$C$206,$B6,Rabu!$A$7:$A$206,">="&DATE(2026,9,28),Rabu!$A$7:$A$206,"<="&DATE(2026,10,4))+SUMIFS(Kamis!$H$7:$H$186,Kamis!$C$7:$C$186,$B6,Kamis!$A$7:$A$186,">="&DATE(2026,9,28),Kamis!$A$7:$A$186,"<="&DATE(2026,10,4))+SUMIFS(Jumat!$H$7:$H$186,Jumat!$C$7:$C$186,$B6,Jumat!$A$7:$A$186,">="&DATE(2026,9,28),Jumat!$A$7:$A$186,"<="&DATE(2026,10,4)) -> 0 | P6: =SUMIFS(Senin!$H$7:$H$146,Senin!$C$7:$C$146,$B6,Senin!$A$7:$A$146,">="&DATE(2026,10,5),Senin!$A$7:$A$146,"<="&DATE(2026,10,11))+SUMIFS(Selasa!$H$7:$H$166,Selasa!$C$7:$C$166,$B6,Selasa!$A$7:$A$166,">="&DATE(2026,10,5),Selasa!$A$7:$A$166,"<="&DATE(2026,10,11))+SUMIFS(Rabu!$H$7:$H$206,Rabu!$C$7:$C$206,$B6,Rabu!$A$7:$A$206,">="&DATE(2026,10,5),Rabu!$A$7:$A$206,"<="&DATE(2026,10,11))+SUMIFS(Kamis!$H$7:$H$186,Kamis!$C$7:$C$186,$B6,Kamis!$A$7:$A$186,">="&DATE(2026,10,5),Kamis!$A$7:$A$186,"<="&DATE(2026,10,11))+SUMIFS(Jumat!$H$7:$H$186,Jumat!$C$7:$C$186,$B6,Jumat!$A$7:$A$186,">="&DATE(2026,10,5),Jumat!$A$7:$A$186,"<="&DATE(2026,10,11)) -> 0 | Q6: =SUMIFS(Senin!$H$7:$H$146,Senin!$C$7:$C$146,$B6,Senin!$A$7:$A$146,">="&DATE(2026,10,12),Senin!$A$7:$A$146,"<="&DATE(2026,10,18))+SUMIFS(Selasa!$H$7:$H$166,Selasa!$C$7:$C$166,$B6,Selasa!$A$7:$A$166,">="&DATE(2026,10,12),Selasa!$A$7:$A$166,"<="&DATE(2026,10,18))+SUMIFS(Rabu!$H$7:$H$206,Rabu!$C$7:$C$206,$B6,Rabu!$A$7:$A$206,">="&DATE(2026,10,12),Rabu!$A$7:$A$206,"<="&DATE(2026,10,18))+SUMIFS(Kamis!$H$7:$H$186,Kamis!$C$7:$C$186,$B6,Kamis!$A$7:$A$186,">="&DATE(2026,10,12),Kamis!$A$7:$A$186,"<="&DATE(2026,10,18))+SUMIFS(Jumat!$H$7:$H$186,Jumat!$C$7:$C$186,$B6,Jumat!$A$7:$A$186,">="&DATE(2026,10,12),Jumat!$A$7:$A$186,"<="&DATE(2026,10,18)) -> 0 | R6: =SUMIFS(Senin!$H$7:$H$146,Senin!$C$7:$C$146,$B6,Senin!$A$7:$A$146,">="&DATE(2026,10,19),Senin!$A$7:$A$146,"<="&DATE(2026,10,25))+SUMIFS(Selasa!$H$7:$H$166,Selasa!$C$7:$C$166,$B6,Selasa!$A$7:$A$166,">="&DATE(2026,10,19),Selasa!$A$7:$A$166,"<="&DATE(2026,10,25))+SUMIFS(Rabu!$H$7:$H$206,Rabu!$C$7:$C$206,$B6,Rabu!$A$7:$A$206,">="&DATE(2026,10,19),Rabu!$A$7:$A$206,"<="&DATE(2026,10,25))+SUMIFS(Kamis!$H$7:$H$186,Kamis!$C$7:$C$186,$B6,Kamis!$A$7:$A$186,">="&DATE(2026,10,19),Kamis!$A$7:$A$186,"<="&DATE(2026,10,25))+SUMIFS(Jumat!$H$7:$H$186,Jumat!$C$7:$C$186,$B6,Jumat!$A$7:$A$186,">="&DATE(2026,10,19),Jumat!$A$7:$A$186,"<="&DATE(2026,10,25)) -> 0 | S6: =SUMIFS(Senin!$H$7:$H$146,Senin!$C$7:$C$146,$B6,Senin!$A$7:$A$146,">="&DATE(2026,10,26),Senin!$A$7:$A$146,"<="&DATE(2026,11,1))+SUMIFS(Selasa!$H$7:$H$166,Selasa!$C$7:$C$166,$B6,Selasa!$A$7:$A$166,">="&DATE(2026,10,26),Selasa!$A$7:$A$166,"<="&DATE(2026,11,1))+SUMIFS(Rabu!$H$7:$H$206,Rabu!$C$7:$C$206,$B6,Rabu!$A$7:$A$206,">="&DATE(2026,10,26),Rabu!$A$7:$A$206,"<="&DATE(2026,11,1))+SUMIFS(Kamis!$H$7:$H$186,Kamis!$C$7:$C$186,$B6,Kamis!$A$7:$A$186,">="&DATE(2026,10,26),Kamis!$A$7:$A$186,"<="&DATE(2026,11,1))+SUMIFS(Jumat!$H$7:$H$186,Jumat!$C$7:$C$186,$B6,Jumat!$A$7:$A$186,">="&DATE(2026,10,26),Jumat!$A$7:$A$186,"<="&DATE(2026,11,1)) -> 0 | T6: =SUMIFS(Senin!$H$7:$H$146,Senin!$C$7:$C$146,$B6,Senin!$A$7:$A$146,">="&DATE(2026,11,2),Senin!$A$7:$A$146,"<="&DATE(2026,11,8))+SUMIFS(Selasa!$H$7:$H$166,Selasa!$C$7:$C$166,$B6,Selasa!$A$7:$A$166,">="&DATE(2026,11,2),Selasa!$A$7:$A$166,"<="&DATE(2026,11,8))+SUMIFS(Rabu!$H$7:$H$206,Rabu!$C$7:$C$206,$B6,Rabu!$A$7:$A$206,">="&DATE(2026,11,2),Rabu!$A$7:$A$206,"<="&DATE(2026,11,8))+SUMIFS(Kamis!$H$7:$H$186,Kamis!$C$7:$C$186,$B6,Kamis!$A$7:$A$186,">="&DATE(2026,11,2),Kamis!$A$7:$A$186,"<="&DATE(2026,11,8))+SUMIFS(Jumat!$H$7:$H$186,Jumat!$C$7:$C$186,$B6,Jumat!$A$7:$A$186,">="&DATE(2026,11,2),Jumat!$A$7:$A$186,"<="&DATE(2026,11,8)) -> 0 | U6: =SUMIFS(Senin!$H$7:$H$146,Senin!$C$7:$C$146,$B6,Senin!$A$7:$A$146,">="&DATE(2026,11,9),Senin!$A$7:$A$146,"<="&DATE(2026,11,15))+SUMIFS(Selasa!$H$7:$H$166,Selasa!$C$7:$C$166,$B6,Selasa!$A$7:$A$166,">="&DATE(2026,11,9),Selasa!$A$7:$A$166,"<="&DATE(2026,11,15))+SUMIFS(Rabu!$H$7:$H$206,Rabu!$C$7:$C$206,$B6,Rabu!$A$7:$A$206,">="&DATE(2026,11,9),Rabu!$A$7:$A$206,"<="&DATE(2026,11,15))+SUMIFS(Kamis!$H$7:$H$186,Kamis!$C$7:$C$186,$B6,Kamis!$A$7:$A$186,">="&DATE(2026,11,9),Kamis!$A$7:$A$186,"<="&DATE(2026,11,15))+SUMIFS(Jumat!$H$7:$H$186,Jumat!$C$7:$C$186,$B6,Jumat!$A$7:$A$186,">="&DATE(2026,11,9),Jumat!$A$7:$A$186,"<="&DATE(2026,11,15)) -> 0 | V6: =SUMIFS(Senin!$H$7:$H$146,Senin!$C$7:$C$146,$B6,Senin!$A$7:$A$146,">="&DATE(2026,11,16),Senin!$A$7:$A$146,"<="&DATE(2026,11,22))+SUMIFS(Selasa!$H$7:$H$166,Selasa!$C$7:$C$166,$B6,Selasa!$A$7:$A$166,">="&DATE(2026,11,16),Selasa!$A$7:$A$166,"<="&DATE(2026,11,22))+SUMIFS(Rabu!$H$7:$H$206,Rabu!$C$7:$C$206,$B6,Rabu!$A$7:$A$206,">="&DATE(2026,11,16),Rabu!$A$7:$A$206,"<="&DATE(2026,11,22))+SUMIFS(Kamis!$H$7:$H$186,Kamis!$C$7:$C$186,$B6,Kamis!$A$7:$A$186,">="&DATE(2026,11,16),Kamis!$A$7:$A$186,"<="&DATE(2026,11,22))+SUMIFS(Jumat!$H$7:$H$186,Jumat!$C$7:$C$186,$B6,Jumat!$A$7:$A$186,">="&DATE(2026,11,16),Jumat!$A$7:$A$186,"<="&DATE(2026,11,22)) -> 0 | W6: =SUMIFS(Senin!$H$7:$H$146,Senin!$C$7:$C$146,$B6,Senin!$A$7:$A$146,">="&DATE(2026,11,23),Senin!$A$7:$A$146,"<="&DATE(2026,11,29))+SUMIFS(Selasa!$H$7:$H$166,Selasa!$C$7:$C$166,$B6,Selasa!$A$7:$A$166,">="&DATE(2026,11,23),Selasa!$A$7:$A$166,"<="&DATE(2026,11,29))+SUMIFS(Rabu!$H$7:$H$206,Rabu!$C$7:$C$206,$B6,Rabu!$A$7:$A$206,">="&DATE(2026,11,23),Rabu!$A$7:$A$206,"<="&DATE(2026,11,29))+SUMIFS(Kamis!$H$7:$H$186,Kamis!$C$7:$C$186,$B6,Kamis!$A$7:$A$186,">="&DATE(2026,11,23),Kamis!$A$7:$A$186,"<="&DATE(2026,11,29))+SUMIFS(Jumat!$H$7:$H$186,Jumat!$C$7:$C$186,$B6,Jumat!$A$7:$A$186,">="&DATE(2026,11,23),Jumat!$A$7:$A$186,"<="&DATE(2026,11,29)) -> 0 | X6: =SUMIFS(Senin!$H$7:$H$146,Senin!$C$7:$C$146,$B6,Senin!$A$7:$A$146,">="&DATE(2026,11,30),Senin!$A$7:$A$146,"<="&DATE(2026,12,6))+SUMIFS(Selasa!$H$7:$H$166,Selasa!$C$7:$C$166,$B6,Selasa!$A$7:$A$166,">="&DATE(2026,11,30),Selasa!$A$7:$A$166,"<="&DATE(2026,12,6))+SUMIFS(Rabu!$H$7:$H$206,Rabu!$C$7:$C$206,$B6,Rabu!$A$7:$A$206,">="&DATE(2026,11,30),Rabu!$A$7:$A$206,"<="&DATE(2026,12,6))+SUMIFS(Kamis!$H$7:$H$186,Kamis!$C$7:$C$186,$B6,Kamis!$A$7:$A$186,">="&DATE(2026,11,30),Kamis!$A$7:$A$186,"<="&DATE(2026,12,6))+SUMIFS(Jumat!$H$7:$H$186,Jumat!$C$7:$C$186,$B6,Jumat!$A$7:$A$186,">="&DATE(2026,11,30),Jumat!$A$7:$A$186,"<="&DATE(2026,12,6)) -> 0 | Y6: =SUMIFS(Senin!$H$7:$H$146,Senin!$C$7:$C$146,$B6,Senin!$A$7:$A$146,">="&DATE(2026,12,7),Senin!$A$7:$A$146,"<="&DATE(2026,12,13))+SUMIFS(Selasa!$H$7:$H$166,Selasa!$C$7:$C$166,$B6,Selasa!$A$7:$A$166,">="&DATE(2026,12,7),Selasa!$A$7:$A$166,"<="&DATE(2026,12,13))+SUMIFS(Rabu!$H$7:$H$206,Rabu!$C$7:$C$206,$B6,Rabu!$A$7:$A$206,">="&DATE(2026,12,7),Rabu!$A$7:$A$206,"<="&DATE(2026,12,13))+SUMIFS(Kamis!$H$7:$H$186,Kamis!$C$7:$C$186,$B6,Kamis!$A$7:$A$186,">="&DATE(2026,12,7),Kamis!$A$7:$A$186,"<="&DATE(2026,12,13))+SUMIFS(Jumat!$H$7:$H$186,Jumat!$C$7:$C$186,$B6,Jumat!$A$7:$A$186,">="&DATE(2026,12,7),Jumat!$A$7:$A$186,"<="&DATE(2026,12,13)) -> 0 | Z6: =SUMIFS(Senin!$H$7:$H$146,Senin!$C$7:$C$146,$B6,Senin!$A$7:$A$146,">="&DATE(2026,12,14),Senin!$A$7:$A$146,"<="&DATE(2026,12,20))+SUMIFS(Selasa!$H$7:$H$166,Selasa!$C$7:$C$166,$B6,Selasa!$A$7:$A$166,">="&DATE(2026,12,14),Selasa!$A$7:$A$166,"<="&DATE(2026,12,20))+SUMIFS(Rabu!$H$7:$H$206,Rabu!$C$7:$C$206,$B6,Rabu!$A$7:$A$206,">="&DATE(2026,12,14),Rabu!$A$7:$A$206,"<="&DATE(2026,12,20))+SUMIFS(Kamis!$H$7:$H$186,Kamis!$C$7:$C$186,$B6,Kamis!$A$7:$A$186,">="&DATE(2026,12,14),Kamis!$A$7:$A$186,"<="&DATE(2026,12,20))+SUMIFS(Jumat!$H$7:$H$186,Jumat!$C$7:$C$186,$B6,Jumat!$A$7:$A$186,">="&DATE(2026,12,14),Jumat!$A$7:$A$186,"<="&DATE(2026,12,20)) -> 0 | AA6: =SUMIFS(Senin!$H$7:$H$146,Senin!$C$7:$C$146,$B6,Senin!$A$7:$A$146,">="&DATE(2026,12,21),Senin!$A$7:$A$146,"<="&DATE(2026,12,27))+SUMIFS(Selasa!$H$7:$H$166,Selasa!$C$7:$C$166,$B6,Selasa!$A$7:$A$166,">="&DATE(2026,12,21),Selasa!$A$7:$A$166,"<="&DATE(2026,12,27))+SUMIFS(Rabu!$H$7:$H$206,Rabu!$C$7:$C$206,$B6,Rabu!$A$7:$A$206,">="&DATE(2026,12,21),Rabu!$A$7:$A$206,"<="&DATE(2026,12,27))+SUMIFS(Kamis!$H$7:$H$186,Kamis!$C$7:$C$186,$B6,Kamis!$A$7:$A$186,">="&DATE(2026,12,21),Kamis!$A$7:$A$186,"<="&DATE(2026,12,27))+SUMIFS(Jumat!$H$7:$H$186,Jumat!$C$7:$C$186,$B6,Jumat!$A$7:$A$186,">="&DATE(2026,12,21),Jumat!$A$7:$A$186,"<="&DATE(2026,12,27)) -> 0 | AB6: =SUMIFS(Senin!$H$7:$H$146,Senin!$C$7:$C$146,$B6,Senin!$A$7:$A$146,">="&DATE(2026,12,28),Senin!$A$7:$A$146,"<="&DATE(2027,1,3))+SUMIFS(Selasa!$H$7:$H$166,Selasa!$C$7:$C$166,$B6,Selasa!$A$7:$A$166,">="&DATE(2026,12,28),Selasa!$A$7:$A$166,"<="&DATE(2027,1,3))+SUMIFS(Rabu!$H$7:$H$206,Rabu!$C$7:$C$206,$B6,Rabu!$A$7:$A$206,">="&DATE(2026,12,28),Rabu!$A$7:$A$206,"<="&DATE(2027,1,3))+SUMIFS(Kamis!$H$7:$H$186,Kamis!$C$7:$C$186,$B6,Kamis!$A$7:$A$186,">="&DATE(2026,12,28),Kamis!$A$7:$A$186,"<="&DATE(2027,1,3))+SUMIFS(Jumat!$H$7:$H$186,Jumat!$C$7:$C$186,$B6,Jumat!$A$7:$A$186,">="&DATE(2026,12,28),Jumat!$A$7:$A$186,"<="&DATE(2027,1,3)) -> 0 | AC6: =SUMIFS(Senin!$H$7:$H$146,Senin!$C$7:$C$146,$B6,Senin!$A$7:$A$146,">="&DATE(2027,1,4),Senin!$A$7:$A$146,"<="&DATE(2027,1,10))+SUMIFS(Selasa!$H$7:$H$166,Selasa!$C$7:$C$166,$B6,Selasa!$A$7:$A$166,">="&DATE(2027,1,4),Selasa!$A$7:$A$166,"<="&DATE(2027,1,10))+SUMIFS(Rabu!$H$7:$H$206,Rabu!$C$7:$C$206,$B6,Rabu!$A$7:$A$206,">="&DATE(2027,1,4),Rabu!$A$7:$A$206,"<="&DATE(2027,1,10))+SUMIFS(Kamis!$H$7:$H$186,Kamis!$C$7:$C$186,$B6,Kamis!$A$7:$A$186,">="&DATE(2027,1,4),Kamis!$A$7:$A$186,"<="&DATE(2027,1,10))+SUMIFS(Jumat!$H$7:$H$186,Jumat!$C$7:$C$186,$B6,Jumat!$A$7:$A$186,">="&DATE(2027,1,4),Jumat!$A$7:$A$186,"<="&DATE(2027,1,10)) -> 0 | AD6: =SUMIFS(Senin!$H$7:$H$146,Senin!$C$7:$C$146,$B6,Senin!$A$7:$A$146,">="&DATE(2027,1,11),Senin!$A$7:$A$146,"<="&DATE(2027,1,17))+SUMIFS(Selasa!$H$7:$H$166,Selasa!$C$7:$C$166,$B6,Selasa!$A$7:$A$166,">="&DATE(2027,1,11),Selasa!$A$7:$A$166,"<="&DATE(2027,1,17))+SUMIFS(Rabu!$H$7:$H$206,Rabu!$C$7:$C$206,$B6,Rabu!$A$7:$A$206,">="&DATE(2027,1,11),Rabu!$A$7:$A$206,"<="&DATE(2027,1,17))+SUMIFS(Kamis!$H$7:$H$186,Kamis!$C$7:$C$186,$B6,Kamis!$A$7:$A$186,">="&DATE(2027,1,11),Kamis!$A$7:$A$186,"<="&DATE(2027,1,17))+SUMIFS(Jumat!$H$7:$H$186,Jumat!$C$7:$C$186,$B6,Jumat!$A$7:$A$186,">="&DATE(2027,1,11),Jumat!$A$7:$A$186,"<="&DATE(2027,1,17)) -> 0
